
package client.core.world;
import java.util.Random;

import net.minecraft.block.Block;
import net.minecraft.world.World;
import net.minecraft.world.gen.feature.WorldGenerator;

public class WorldGenBossArena extends WorldGenerator
{
	protected int[] GetValidSpawnBlocks() {
		return new int[] {
			//Block.stone.blockID,
			Block.grass.blockID,
			/*Block.dirt.blockID,
			Block.bedrock.blockID,
			Block.lavaStill.blockID,
			Block.waterStill.blockID*/
		};
	}

	public boolean LocationIsValidSpawn(World world, int i, int j, int k){
		int distanceToAir = 0;
		int checkID = world.getBlockId(i, j, k);

		while (checkID != 0){
			distanceToAir++;
			checkID = world.getBlockId(i, j + distanceToAir, k);
		}

		if (distanceToAir > 3){
			return false;
		}
		j += distanceToAir - 1;

		int blockID = world.getBlockId(i, j, k);
		int blockIDAbove = world.getBlockId(i, j+1, k);
		int blockIDBelow = world.getBlockId(i, j-1, k);
		for (int x : GetValidSpawnBlocks()){
			if (blockIDAbove != 0){
				return false;
			}
			if (blockID == x){
				return true;
			}else if (blockID == Block.snow.blockID && blockIDBelow == x){
				return true;
			}
		}
		return false;
	}

	public WorldGenBossArena() { }

	public boolean generate(World world, Random rand, int i, int j, int k) {
		//check that each corner is one of the valid spawn blocks
		if(!LocationIsValidSpawn(world, i, j, k) || !LocationIsValidSpawn(world, i + 47, j, k) || !LocationIsValidSpawn(world, i + 47, j, k + 53) || !LocationIsValidSpawn(world, i, j, k + 53))
		{
			return false;
		}
		System.out.println("Generating Valid");

		world.setBlock(i + 2, j + 0, k + 1, Block.stoneBrick.blockID);
		world.setBlock(i + 2, j + 0, k + 2, Block.stoneBrick.blockID);
		world.setBlock(i + 2, j + 0, k + 3, Block.stoneBrick.blockID);
		world.setBlock(i + 2, j + 0, k + 4, Block.stoneBrick.blockID);
		world.setBlock(i + 2, j + 0, k + 5, Block.stoneBrick.blockID);
		world.setBlock(i + 2, j + 0, k + 6, Block.stoneBrick.blockID);
		world.setBlock(i + 2, j + 0, k + 7, Block.stoneBrick.blockID);
		world.setBlock(i + 2, j + 0, k + 8, Block.stoneBrick.blockID);
		world.setBlock(i + 2, j + 0, k + 9, Block.stoneBrick.blockID);
		world.setBlock(i + 2, j + 0, k + 10, Block.stoneBrick.blockID);
		world.setBlock(i + 2, j + 0, k + 11, Block.stoneBrick.blockID);
		world.setBlock(i + 2, j + 0, k + 12, Block.stoneBrick.blockID);
		world.setBlock(i + 2, j + 0, k + 13, Block.stoneBrick.blockID);
		world.setBlock(i + 2, j + 0, k + 14, Block.stoneBrick.blockID);
		world.setBlock(i + 2, j + 0, k + 15, Block.stoneBrick.blockID);
		world.setBlock(i + 2, j + 0, k + 16, Block.stoneBrick.blockID);
		world.setBlock(i + 2, j + 0, k + 17, Block.stoneBrick.blockID);
		world.setBlock(i + 2, j + 0, k + 18, Block.stoneBrick.blockID);
		world.setBlock(i + 2, j + 0, k + 19, Block.stoneBrick.blockID);
		world.setBlock(i + 2, j + 0, k + 20, Block.stoneBrick.blockID);
		world.setBlock(i + 2, j + 0, k + 21, Block.stoneBrick.blockID);
		world.setBlock(i + 2, j + 0, k + 22, Block.stoneBrick.blockID);
		world.setBlock(i + 2, j + 0, k + 23, Block.stoneBrick.blockID);
		world.setBlock(i + 2, j + 0, k + 24, Block.stoneBrick.blockID);
		world.setBlock(i + 2, j + 0, k + 25, Block.stoneBrick.blockID);
		world.setBlock(i + 2, j + 0, k + 26, Block.stoneBrick.blockID);
		world.setBlock(i + 2, j + 0, k + 27, Block.stoneBrick.blockID);
		world.setBlock(i + 2, j + 0, k + 28, Block.stoneBrick.blockID);
		world.setBlock(i + 2, j + 0, k + 29, Block.stoneBrick.blockID);
		world.setBlock(i + 2, j + 0, k + 30, Block.stoneBrick.blockID);
		world.setBlock(i + 2, j + 0, k + 31, Block.stoneBrick.blockID);
		world.setBlock(i + 2, j + 0, k + 32, Block.stoneBrick.blockID);
		world.setBlock(i + 2, j + 0, k + 33, Block.stoneBrick.blockID);
		world.setBlock(i + 2, j + 0, k + 34, Block.stoneBrick.blockID);
		world.setBlock(i + 2, j + 0, k + 35, Block.stoneBrick.blockID);
		world.setBlock(i + 2, j + 0, k + 36, Block.stoneBrick.blockID);
		world.setBlock(i + 2, j + 0, k + 37, Block.stoneBrick.blockID);
		world.setBlock(i + 2, j + 0, k + 38, Block.stoneBrick.blockID);
		world.setBlock(i + 2, j + 0, k + 39, Block.stoneBrick.blockID);
		world.setBlock(i + 2, j + 0, k + 40, Block.stoneBrick.blockID);
		world.setBlock(i + 2, j + 0, k + 41, Block.stoneBrick.blockID);
		world.setBlock(i + 2, j + 0, k + 42, Block.stoneBrick.blockID);
		world.setBlock(i + 2, j + 0, k + 43, Block.stoneBrick.blockID);
		world.setBlock(i + 2, j + 0, k + 44, Block.stoneBrick.blockID);
		world.setBlock(i + 2, j + 0, k + 45, Block.stoneBrick.blockID);
		world.setBlock(i + 2, j + 0, k + 46, Block.stoneBrick.blockID);
		world.setBlock(i + 2, j + 0, k + 47, Block.stoneBrick.blockID);
		world.setBlock(i + 2, j + 0, k + 48, Block.stoneBrick.blockID);
		world.setBlock(i + 2, j + 0, k + 49, Block.stoneBrick.blockID);
		world.setBlock(i + 2, j + 0, k + 50, Block.stoneBrick.blockID);
		world.setBlock(i + 2, j + 0, k + 51, Block.stoneBrick.blockID);
		world.setBlock(i + 2, j + 1, k + 1, Block.stoneBrick.blockID);
		world.setBlock(i + 2, j + 1, k + 2, Block.stoneBrick.blockID);
		world.setBlock(i + 2, j + 1, k + 3, Block.stoneBrick.blockID);
		world.setBlock(i + 2, j + 1, k + 4, Block.stoneBrick.blockID);
		world.setBlock(i + 2, j + 1, k + 5, Block.stoneBrick.blockID);
		world.setBlock(i + 2, j + 1, k + 6, Block.stoneBrick.blockID);
		world.setBlock(i + 2, j + 1, k + 7, Block.stoneBrick.blockID);
		world.setBlock(i + 2, j + 1, k + 8, Block.stoneBrick.blockID);
		world.setBlock(i + 2, j + 1, k + 9, Block.stoneBrick.blockID);
		world.setBlock(i + 2, j + 1, k + 10, Block.stoneBrick.blockID);
		world.setBlock(i + 2, j + 1, k + 11, Block.stoneBrick.blockID);
		world.setBlock(i + 2, j + 1, k + 12, Block.stoneBrick.blockID);
		world.setBlock(i + 2, j + 1, k + 13, Block.stoneBrick.blockID);
		world.setBlock(i + 2, j + 1, k + 14, Block.stoneBrick.blockID);
		world.setBlock(i + 2, j + 1, k + 15, Block.stoneBrick.blockID);
		world.setBlock(i + 2, j + 1, k + 16, Block.stoneBrick.blockID);
		world.setBlock(i + 2, j + 1, k + 17, Block.stoneBrick.blockID);
		world.setBlock(i + 2, j + 1, k + 18, Block.stoneBrick.blockID);
		world.setBlock(i + 2, j + 1, k + 19, Block.stoneBrick.blockID);
		world.setBlock(i + 2, j + 1, k + 20, Block.stoneBrick.blockID);
		world.setBlock(i + 2, j + 1, k + 21, Block.stoneBrick.blockID);
		world.setBlock(i + 2, j + 1, k + 22, Block.stoneBrick.blockID);
		world.setBlock(i + 2, j + 1, k + 23, Block.stoneBrick.blockID);
		world.setBlock(i + 2, j + 1, k + 24, Block.stoneBrick.blockID);
		world.setBlock(i + 2, j + 1, k + 25, Block.stoneBrick.blockID);
		world.setBlock(i + 2, j + 1, k + 26, Block.stoneBrick.blockID);
		world.setBlock(i + 2, j + 1, k + 27, Block.stoneBrick.blockID);
		world.setBlock(i + 2, j + 1, k + 28, Block.stoneBrick.blockID);
		world.setBlock(i + 2, j + 1, k + 29, Block.stoneBrick.blockID);
		world.setBlock(i + 2, j + 1, k + 30, Block.stoneBrick.blockID);
		world.setBlock(i + 2, j + 1, k + 31, Block.stoneBrick.blockID);
		world.setBlock(i + 2, j + 1, k + 32, Block.stoneBrick.blockID);
		world.setBlock(i + 2, j + 1, k + 33, Block.stoneBrick.blockID);
		world.setBlock(i + 2, j + 1, k + 34, Block.stoneBrick.blockID);
		world.setBlock(i + 2, j + 1, k + 35, Block.stoneBrick.blockID);
		world.setBlock(i + 2, j + 1, k + 36, Block.stoneBrick.blockID);
		world.setBlock(i + 2, j + 1, k + 37, Block.stoneBrick.blockID);
		world.setBlock(i + 2, j + 1, k + 38, Block.stoneBrick.blockID);
		world.setBlock(i + 2, j + 1, k + 39, Block.stoneBrick.blockID);
		world.setBlock(i + 2, j + 1, k + 40, Block.stoneBrick.blockID);
		world.setBlock(i + 2, j + 1, k + 41, Block.stoneBrick.blockID);
		world.setBlock(i + 2, j + 1, k + 42, Block.stoneBrick.blockID);
		world.setBlock(i + 2, j + 1, k + 43, Block.stoneBrick.blockID);
		world.setBlock(i + 2, j + 1, k + 44, Block.stoneBrick.blockID);
		world.setBlock(i + 2, j + 1, k + 45, Block.stoneBrick.blockID);
		world.setBlock(i + 2, j + 1, k + 46, Block.stoneBrick.blockID);
		world.setBlock(i + 2, j + 1, k + 47, Block.stoneBrick.blockID);
		world.setBlock(i + 2, j + 1, k + 48, Block.stoneBrick.blockID);
		world.setBlock(i + 2, j + 1, k + 49, Block.stoneBrick.blockID);
		world.setBlock(i + 2, j + 1, k + 50, Block.stoneBrick.blockID);
		world.setBlock(i + 2, j + 1, k + 51, Block.stoneBrick.blockID);
		world.setBlock(i + 2, j + 2, k + 1, Block.stoneBrick.blockID);
		world.setBlock(i + 2, j + 2, k + 2, Block.stoneBrick.blockID);
		world.setBlock(i + 2, j + 2, k + 3, Block.stoneBrick.blockID);
		world.setBlock(i + 2, j + 2, k + 4, Block.stoneBrick.blockID);
		world.setBlock(i + 2, j + 2, k + 5, Block.stoneBrick.blockID);
		world.setBlock(i + 2, j + 2, k + 6, Block.stoneBrick.blockID);
		world.setBlock(i + 2, j + 2, k + 7, Block.stoneBrick.blockID);
		world.setBlock(i + 2, j + 2, k + 8, Block.stoneBrick.blockID);
		world.setBlock(i + 2, j + 2, k + 9, Block.stoneBrick.blockID);
		world.setBlock(i + 2, j + 2, k + 10, Block.stoneBrick.blockID);
		world.setBlock(i + 2, j + 2, k + 11, Block.stoneBrick.blockID);
		world.setBlock(i + 2, j + 2, k + 12, Block.stoneBrick.blockID);
		world.setBlock(i + 2, j + 2, k + 13, Block.stoneBrick.blockID);
		world.setBlock(i + 2, j + 2, k + 14, Block.stoneBrick.blockID);
		world.setBlock(i + 2, j + 2, k + 15, Block.stoneBrick.blockID);
		world.setBlock(i + 2, j + 2, k + 16, Block.stoneBrick.blockID);
		world.setBlock(i + 2, j + 2, k + 17, Block.stoneBrick.blockID);
		world.setBlock(i + 2, j + 2, k + 18, Block.stoneBrick.blockID);
		world.setBlock(i + 2, j + 2, k + 19, Block.stoneBrick.blockID);
		world.setBlock(i + 2, j + 2, k + 20, Block.stoneBrick.blockID);
		world.setBlock(i + 2, j + 2, k + 21, Block.stoneBrick.blockID);
		world.setBlock(i + 2, j + 2, k + 22, Block.stoneBrick.blockID);
		world.setBlock(i + 2, j + 2, k + 23, Block.stoneBrick.blockID);
		world.setBlock(i + 2, j + 2, k + 24, Block.stoneBrick.blockID);
		world.setBlock(i + 2, j + 2, k + 25, Block.stoneBrick.blockID);
		world.setBlock(i + 2, j + 2, k + 26, Block.stoneBrick.blockID);
		world.setBlock(i + 2, j + 2, k + 27, Block.stoneBrick.blockID);
		world.setBlock(i + 2, j + 2, k + 28, Block.stoneBrick.blockID);
		world.setBlock(i + 2, j + 2, k + 29, Block.stoneBrick.blockID);
		world.setBlock(i + 2, j + 2, k + 30, Block.stoneBrick.blockID);
		world.setBlock(i + 2, j + 2, k + 31, Block.stoneBrick.blockID);
		world.setBlock(i + 2, j + 2, k + 32, Block.stoneBrick.blockID);
		world.setBlock(i + 2, j + 2, k + 33, Block.stoneBrick.blockID);
		world.setBlock(i + 2, j + 2, k + 34, Block.stoneBrick.blockID);
		world.setBlock(i + 2, j + 2, k + 35, Block.stoneBrick.blockID);
		world.setBlock(i + 2, j + 2, k + 36, Block.stoneBrick.blockID);
		world.setBlock(i + 2, j + 2, k + 37, Block.stoneBrick.blockID);
		world.setBlock(i + 2, j + 2, k + 38, Block.stoneBrick.blockID);
		world.setBlock(i + 2, j + 2, k + 39, Block.stoneBrick.blockID);
		world.setBlock(i + 2, j + 2, k + 40, Block.stoneBrick.blockID);
		world.setBlock(i + 2, j + 2, k + 41, Block.stoneBrick.blockID);
		world.setBlock(i + 2, j + 2, k + 42, Block.stoneBrick.blockID);
		world.setBlock(i + 2, j + 2, k + 43, Block.stoneBrick.blockID);
		world.setBlock(i + 2, j + 2, k + 44, Block.stoneBrick.blockID);
		world.setBlock(i + 2, j + 2, k + 45, Block.stoneBrick.blockID);
		world.setBlock(i + 2, j + 2, k + 46, Block.stoneBrick.blockID);
		world.setBlock(i + 2, j + 2, k + 47, Block.stoneBrick.blockID);
		world.setBlock(i + 2, j + 2, k + 48, Block.stoneBrick.blockID);
		world.setBlock(i + 2, j + 2, k + 49, Block.stoneBrick.blockID);
		world.setBlock(i + 2, j + 2, k + 50, Block.stoneBrick.blockID);
		world.setBlock(i + 2, j + 2, k + 51, Block.stoneBrick.blockID);
		world.setBlock(i + 2, j + 3, k + 1, Block.stoneBrick.blockID);
		world.setBlock(i + 2, j + 3, k + 2, Block.stoneBrick.blockID);
		world.setBlock(i + 2, j + 3, k + 3, Block.stoneBrick.blockID);
		world.setBlock(i + 2, j + 3, k + 4, Block.stoneBrick.blockID);
		world.setBlock(i + 2, j + 3, k + 5, Block.stoneBrick.blockID);
		world.setBlock(i + 2, j + 3, k + 6, Block.stoneBrick.blockID);
		world.setBlock(i + 2, j + 3, k + 7, Block.stoneBrick.blockID);
		world.setBlock(i + 2, j + 3, k + 8, Block.stoneBrick.blockID);
		world.setBlock(i + 2, j + 3, k + 9, Block.stoneBrick.blockID);
		world.setBlock(i + 2, j + 3, k + 10, Block.stoneBrick.blockID);
		world.setBlock(i + 2, j + 3, k + 11, Block.stoneBrick.blockID);
		world.setBlock(i + 2, j + 3, k + 12, Block.stoneBrick.blockID);
		world.setBlock(i + 2, j + 3, k + 13, Block.stoneBrick.blockID);
		world.setBlock(i + 2, j + 3, k + 14, Block.stoneBrick.blockID);
		world.setBlock(i + 2, j + 3, k + 15, Block.stoneBrick.blockID);
		world.setBlock(i + 2, j + 3, k + 16, Block.stoneBrick.blockID);
		world.setBlock(i + 2, j + 3, k + 17, Block.stoneBrick.blockID);
		world.setBlock(i + 2, j + 3, k + 18, Block.stoneBrick.blockID);
		world.setBlock(i + 2, j + 3, k + 19, Block.stoneBrick.blockID);
		world.setBlock(i + 2, j + 3, k + 20, Block.stoneBrick.blockID);
		world.setBlock(i + 2, j + 3, k + 21, Block.stoneBrick.blockID);
		world.setBlock(i + 2, j + 3, k + 22, Block.stoneBrick.blockID);
		world.setBlock(i + 2, j + 3, k + 23, Block.stoneBrick.blockID);
		world.setBlock(i + 2, j + 3, k + 24, Block.stoneBrick.blockID);
		world.setBlock(i + 2, j + 3, k + 25, Block.stoneBrick.blockID);
		world.setBlock(i + 2, j + 3, k + 26, Block.stoneBrick.blockID);
		world.setBlock(i + 2, j + 3, k + 27, Block.stoneBrick.blockID);
		world.setBlock(i + 2, j + 3, k + 28, Block.stoneBrick.blockID);
		world.setBlock(i + 2, j + 3, k + 29, Block.stoneBrick.blockID);
		world.setBlock(i + 2, j + 3, k + 30, Block.stoneBrick.blockID);
		world.setBlock(i + 2, j + 3, k + 31, Block.stoneBrick.blockID);
		world.setBlock(i + 2, j + 3, k + 32, Block.stoneBrick.blockID);
		world.setBlock(i + 2, j + 3, k + 33, Block.stoneBrick.blockID);
		world.setBlock(i + 2, j + 3, k + 34, Block.stoneBrick.blockID);
		world.setBlock(i + 2, j + 3, k + 35, Block.stoneBrick.blockID);
		world.setBlock(i + 2, j + 3, k + 36, Block.stoneBrick.blockID);
		world.setBlock(i + 2, j + 3, k + 37, Block.stoneBrick.blockID);
		world.setBlock(i + 2, j + 3, k + 38, Block.stoneBrick.blockID);
		world.setBlock(i + 2, j + 3, k + 39, Block.stoneBrick.blockID);
		world.setBlock(i + 2, j + 3, k + 40, Block.stoneBrick.blockID);
		world.setBlock(i + 2, j + 3, k + 41, Block.stoneBrick.blockID);
		world.setBlock(i + 2, j + 3, k + 42, Block.stoneBrick.blockID);
		world.setBlock(i + 2, j + 3, k + 43, Block.stoneBrick.blockID);
		world.setBlock(i + 2, j + 3, k + 44, Block.stoneBrick.blockID);
		world.setBlock(i + 2, j + 3, k + 45, Block.stoneBrick.blockID);
		world.setBlock(i + 2, j + 3, k + 46, Block.stoneBrick.blockID);
		world.setBlock(i + 2, j + 3, k + 47, Block.stoneBrick.blockID);
		world.setBlock(i + 2, j + 3, k + 48, Block.stoneBrick.blockID);
		world.setBlock(i + 2, j + 3, k + 49, Block.stoneBrick.blockID);
		world.setBlock(i + 2, j + 3, k + 50, Block.stoneBrick.blockID);
		world.setBlock(i + 2, j + 3, k + 51, Block.stoneBrick.blockID);
		world.setBlock(i + 2, j + 4, k + 1, Block.stoneBrick.blockID);
		world.setBlock(i + 2, j + 4, k + 2, Block.stoneBrick.blockID);
		world.setBlock(i + 2, j + 4, k + 3, Block.stoneBrick.blockID);
		world.setBlock(i + 2, j + 4, k + 4, Block.stoneBrick.blockID);
		world.setBlock(i + 2, j + 4, k + 5, Block.stoneBrick.blockID);
		world.setBlock(i + 2, j + 4, k + 6, Block.stoneBrick.blockID);
		world.setBlock(i + 2, j + 4, k + 7, Block.stoneBrick.blockID);
		world.setBlock(i + 2, j + 4, k + 8, Block.stoneBrick.blockID);
		world.setBlock(i + 2, j + 4, k + 9, Block.stoneBrick.blockID);
		world.setBlock(i + 2, j + 4, k + 10, Block.stoneBrick.blockID);
		world.setBlock(i + 2, j + 4, k + 11, Block.stoneBrick.blockID);
		world.setBlock(i + 2, j + 4, k + 12, Block.stoneBrick.blockID);
		world.setBlock(i + 2, j + 4, k + 13, Block.stoneBrick.blockID);
		world.setBlock(i + 2, j + 4, k + 14, Block.stoneBrick.blockID);
		world.setBlock(i + 2, j + 4, k + 15, Block.stoneBrick.blockID);
		world.setBlock(i + 2, j + 4, k + 16, Block.stoneBrick.blockID);
		world.setBlock(i + 2, j + 4, k + 17, Block.stoneBrick.blockID);
		world.setBlock(i + 2, j + 4, k + 18, Block.stoneBrick.blockID);
		world.setBlock(i + 2, j + 4, k + 19, Block.stoneBrick.blockID);
		world.setBlock(i + 2, j + 4, k + 20, Block.stoneBrick.blockID);
		world.setBlock(i + 2, j + 4, k + 21, Block.stoneBrick.blockID);
		world.setBlock(i + 2, j + 4, k + 22, Block.stoneBrick.blockID);
		world.setBlock(i + 2, j + 4, k + 23, Block.stoneBrick.blockID);
		world.setBlock(i + 2, j + 4, k + 24, Block.stoneBrick.blockID);
		world.setBlock(i + 2, j + 4, k + 25, Block.stoneBrick.blockID);
		world.setBlock(i + 2, j + 4, k + 26, Block.stoneBrick.blockID);
		world.setBlock(i + 2, j + 4, k + 27, Block.stoneBrick.blockID);
		world.setBlock(i + 2, j + 4, k + 28, Block.stoneBrick.blockID);
		world.setBlock(i + 2, j + 4, k + 29, Block.stoneBrick.blockID);
		world.setBlock(i + 2, j + 4, k + 30, Block.stoneBrick.blockID);
		world.setBlock(i + 2, j + 4, k + 31, Block.stoneBrick.blockID);
		world.setBlock(i + 2, j + 4, k + 32, Block.stoneBrick.blockID);
		world.setBlock(i + 2, j + 4, k + 33, Block.stoneBrick.blockID);
		world.setBlock(i + 2, j + 4, k + 34, Block.stoneBrick.blockID);
		world.setBlock(i + 2, j + 4, k + 35, Block.stoneBrick.blockID);
		world.setBlock(i + 2, j + 4, k + 36, Block.stoneBrick.blockID);
		world.setBlock(i + 2, j + 4, k + 37, Block.stoneBrick.blockID);
		world.setBlock(i + 2, j + 4, k + 38, Block.stoneBrick.blockID);
		world.setBlock(i + 2, j + 4, k + 39, Block.stoneBrick.blockID);
		world.setBlock(i + 2, j + 4, k + 40, Block.stoneBrick.blockID);
		world.setBlock(i + 2, j + 4, k + 41, Block.stoneBrick.blockID);
		world.setBlock(i + 2, j + 4, k + 42, Block.stoneBrick.blockID);
		world.setBlock(i + 2, j + 4, k + 43, Block.stoneBrick.blockID);
		world.setBlock(i + 2, j + 4, k + 44, Block.stoneBrick.blockID);
		world.setBlock(i + 2, j + 4, k + 45, Block.stoneBrick.blockID);
		world.setBlock(i + 2, j + 4, k + 46, Block.stoneBrick.blockID);
		world.setBlock(i + 2, j + 4, k + 47, Block.stoneBrick.blockID);
		world.setBlock(i + 2, j + 4, k + 48, Block.stoneBrick.blockID);
		world.setBlock(i + 2, j + 4, k + 49, Block.stoneBrick.blockID);
		world.setBlock(i + 2, j + 4, k + 50, Block.stoneBrick.blockID);
		world.setBlock(i + 2, j + 4, k + 51, Block.stoneBrick.blockID);
		world.setBlock(i + 2, j + 5, k + 1, Block.stoneBrick.blockID);
		world.setBlock(i + 2, j + 5, k + 2, Block.stoneBrick.blockID);
		world.setBlock(i + 2, j + 5, k + 3, Block.stoneBrick.blockID);
		world.setBlock(i + 2, j + 5, k + 4, Block.stoneBrick.blockID);
		world.setBlock(i + 2, j + 5, k + 5, Block.stoneBrick.blockID);
		world.setBlock(i + 2, j + 5, k + 6, Block.stoneBrick.blockID);
		world.setBlock(i + 2, j + 5, k + 7, Block.stoneBrick.blockID);
		world.setBlock(i + 2, j + 5, k + 8, Block.stoneBrick.blockID);
		world.setBlock(i + 2, j + 5, k + 9, Block.stoneBrick.blockID);
		world.setBlock(i + 2, j + 5, k + 10, Block.stoneBrick.blockID);
		world.setBlock(i + 2, j + 5, k + 11, Block.stoneBrick.blockID);
		world.setBlock(i + 2, j + 5, k + 12, Block.stoneBrick.blockID);
		world.setBlock(i + 2, j + 5, k + 13, Block.stoneBrick.blockID);
		world.setBlock(i + 2, j + 5, k + 14, Block.stoneBrick.blockID);
		world.setBlock(i + 2, j + 5, k + 15, Block.stoneBrick.blockID);
		world.setBlock(i + 2, j + 5, k + 16, Block.stoneBrick.blockID);
		world.setBlock(i + 2, j + 5, k + 17, Block.stoneBrick.blockID);
		world.setBlock(i + 2, j + 5, k + 18, Block.stoneBrick.blockID);
		world.setBlock(i + 2, j + 5, k + 19, Block.stoneBrick.blockID);
		world.setBlock(i + 2, j + 5, k + 20, Block.stoneBrick.blockID);
		world.setBlock(i + 2, j + 5, k + 21, Block.stoneBrick.blockID);
		world.setBlock(i + 2, j + 5, k + 22, Block.stoneBrick.blockID);
		world.setBlock(i + 2, j + 5, k + 23, Block.stoneBrick.blockID);
		world.setBlock(i + 2, j + 5, k + 24, Block.stoneBrick.blockID);
		world.setBlock(i + 2, j + 5, k + 25, Block.stoneBrick.blockID);
		world.setBlock(i + 2, j + 5, k + 26, Block.stoneBrick.blockID);
		world.setBlock(i + 2, j + 5, k + 27, Block.stoneBrick.blockID);
		world.setBlock(i + 2, j + 5, k + 28, Block.stoneBrick.blockID);
		world.setBlock(i + 2, j + 5, k + 29, Block.stoneBrick.blockID);
		world.setBlock(i + 2, j + 5, k + 30, Block.stoneBrick.blockID);
		world.setBlock(i + 2, j + 5, k + 31, Block.stoneBrick.blockID);
		world.setBlock(i + 2, j + 5, k + 32, Block.stoneBrick.blockID);
		world.setBlock(i + 2, j + 5, k + 33, Block.stoneBrick.blockID);
		world.setBlock(i + 2, j + 5, k + 34, Block.stoneBrick.blockID);
		world.setBlock(i + 2, j + 5, k + 35, Block.stoneBrick.blockID);
		world.setBlock(i + 2, j + 5, k + 36, Block.stoneBrick.blockID);
		world.setBlock(i + 2, j + 5, k + 37, Block.stoneBrick.blockID);
		world.setBlock(i + 2, j + 5, k + 38, Block.stoneBrick.blockID);
		world.setBlock(i + 2, j + 5, k + 39, Block.stoneBrick.blockID);
		world.setBlock(i + 2, j + 5, k + 40, Block.stoneBrick.blockID);
		world.setBlock(i + 2, j + 5, k + 41, Block.stoneBrick.blockID);
		world.setBlock(i + 2, j + 5, k + 42, Block.stoneBrick.blockID);
		world.setBlock(i + 2, j + 5, k + 43, Block.stoneBrick.blockID);
		world.setBlock(i + 2, j + 5, k + 44, Block.stoneBrick.blockID);
		world.setBlock(i + 2, j + 5, k + 45, Block.stoneBrick.blockID);
		world.setBlock(i + 2, j + 5, k + 46, Block.stoneBrick.blockID);
		world.setBlock(i + 2, j + 5, k + 47, Block.stoneBrick.blockID);
		world.setBlock(i + 2, j + 5, k + 48, Block.stoneBrick.blockID);
		world.setBlock(i + 2, j + 5, k + 49, Block.stoneBrick.blockID);
		world.setBlock(i + 2, j + 5, k + 50, Block.stoneBrick.blockID);
		world.setBlock(i + 2, j + 5, k + 51, Block.stoneBrick.blockID);
		world.setBlock(i + 2, j + 6, k + 1, Block.stoneBrick.blockID);
		world.setBlock(i + 2, j + 6, k + 2, Block.stoneBrick.blockID);
		world.setBlock(i + 2, j + 6, k + 3, Block.stoneBrick.blockID);
		world.setBlock(i + 2, j + 6, k + 4, Block.stoneBrick.blockID);
		world.setBlock(i + 2, j + 6, k + 5, Block.stoneBrick.blockID);
		world.setBlock(i + 2, j + 6, k + 6, Block.stoneBrick.blockID);
		world.setBlock(i + 2, j + 6, k + 7, Block.stoneBrick.blockID);
		world.setBlock(i + 2, j + 6, k + 8, Block.stoneBrick.blockID);
		world.setBlock(i + 2, j + 6, k + 9, Block.stoneBrick.blockID);
		world.setBlock(i + 2, j + 6, k + 10, Block.stoneBrick.blockID);
		world.setBlock(i + 2, j + 6, k + 11, Block.stoneBrick.blockID);
		world.setBlock(i + 2, j + 6, k + 12, Block.stoneBrick.blockID);
		world.setBlock(i + 2, j + 6, k + 13, Block.stoneBrick.blockID);
		world.setBlock(i + 2, j + 6, k + 14, Block.stoneBrick.blockID);
		world.setBlock(i + 2, j + 6, k + 15, Block.stoneBrick.blockID);
		world.setBlock(i + 2, j + 6, k + 16, Block.stoneBrick.blockID);
		world.setBlock(i + 2, j + 6, k + 17, Block.stoneBrick.blockID);
		world.setBlock(i + 2, j + 6, k + 18, Block.stoneBrick.blockID);
		world.setBlock(i + 2, j + 6, k + 19, Block.stoneBrick.blockID);
		world.setBlock(i + 2, j + 6, k + 20, Block.stoneBrick.blockID);
		world.setBlock(i + 2, j + 6, k + 21, Block.stoneBrick.blockID);
		world.setBlock(i + 2, j + 6, k + 22, Block.stoneBrick.blockID);
		world.setBlock(i + 2, j + 6, k + 23, Block.stoneBrick.blockID);
		world.setBlock(i + 2, j + 6, k + 24, Block.stoneBrick.blockID);
		world.setBlock(i + 2, j + 6, k + 25, Block.stoneBrick.blockID);
		world.setBlock(i + 2, j + 6, k + 26, Block.stoneBrick.blockID);
		world.setBlock(i + 2, j + 6, k + 27, Block.stoneBrick.blockID);
		world.setBlock(i + 2, j + 6, k + 28, Block.stoneBrick.blockID);
		world.setBlock(i + 2, j + 6, k + 29, Block.stoneBrick.blockID);
		world.setBlock(i + 2, j + 6, k + 30, Block.stoneBrick.blockID);
		world.setBlock(i + 2, j + 6, k + 31, Block.stoneBrick.blockID);
		world.setBlock(i + 2, j + 6, k + 32, Block.stoneBrick.blockID);
		world.setBlock(i + 2, j + 6, k + 33, Block.stoneBrick.blockID);
		world.setBlock(i + 2, j + 6, k + 34, Block.stoneBrick.blockID);
		world.setBlock(i + 2, j + 6, k + 35, Block.stoneBrick.blockID);
		world.setBlock(i + 2, j + 6, k + 36, Block.stoneBrick.blockID);
		world.setBlock(i + 2, j + 6, k + 37, Block.stoneBrick.blockID);
		world.setBlock(i + 2, j + 6, k + 38, Block.stoneBrick.blockID);
		world.setBlock(i + 2, j + 6, k + 39, Block.stoneBrick.blockID);
		world.setBlock(i + 2, j + 6, k + 40, Block.stoneBrick.blockID);
		world.setBlock(i + 2, j + 6, k + 41, Block.stoneBrick.blockID);
		world.setBlock(i + 2, j + 6, k + 42, Block.stoneBrick.blockID);
		world.setBlock(i + 2, j + 6, k + 43, Block.stoneBrick.blockID);
		world.setBlock(i + 2, j + 6, k + 44, Block.stoneBrick.blockID);
		world.setBlock(i + 2, j + 6, k + 45, Block.stoneBrick.blockID);
		world.setBlock(i + 2, j + 6, k + 46, Block.stoneBrick.blockID);
		world.setBlock(i + 2, j + 6, k + 47, Block.stoneBrick.blockID);
		world.setBlock(i + 2, j + 6, k + 48, Block.stoneBrick.blockID);
		world.setBlock(i + 2, j + 6, k + 49, Block.stoneBrick.blockID);
		world.setBlock(i + 2, j + 6, k + 50, Block.stoneBrick.blockID);
		world.setBlock(i + 2, j + 6, k + 51, Block.stoneBrick.blockID);
		world.setBlock(i + 2, j + 7, k + 1, Block.stoneBrick.blockID);
		world.setBlock(i + 2, j + 7, k + 3, Block.stoneBrick.blockID);
		world.setBlock(i + 2, j + 7, k + 5, Block.stoneBrick.blockID);
		world.setBlock(i + 2, j + 7, k + 7, Block.stoneBrick.blockID);
		world.setBlock(i + 2, j + 7, k + 9, Block.stoneBrick.blockID);
		world.setBlock(i + 2, j + 7, k + 11, Block.stoneBrick.blockID);
		world.setBlock(i + 2, j + 7, k + 13, Block.stoneBrick.blockID);
		world.setBlock(i + 2, j + 7, k + 15, Block.stoneBrick.blockID);
		world.setBlock(i + 2, j + 7, k + 17, Block.stoneBrick.blockID);
		world.setBlock(i + 2, j + 7, k + 19, Block.stoneBrick.blockID);
		world.setBlock(i + 2, j + 7, k + 21, Block.stoneBrick.blockID);
		world.setBlock(i + 2, j + 7, k + 23, Block.stoneBrick.blockID);
		world.setBlock(i + 2, j + 7, k + 25, Block.stoneBrick.blockID);
		world.setBlock(i + 2, j + 7, k + 27, Block.stoneBrick.blockID);
		world.setBlock(i + 2, j + 7, k + 29, Block.stoneBrick.blockID);
		world.setBlock(i + 2, j + 7, k + 31, Block.stoneBrick.blockID);
		world.setBlock(i + 2, j + 7, k + 33, Block.stoneBrick.blockID);
		world.setBlock(i + 2, j + 7, k + 35, Block.stoneBrick.blockID);
		world.setBlock(i + 2, j + 7, k + 37, Block.stoneBrick.blockID);
		world.setBlock(i + 2, j + 7, k + 39, Block.stoneBrick.blockID);
		world.setBlock(i + 2, j + 7, k + 41, Block.stoneBrick.blockID);
		world.setBlock(i + 2, j + 7, k + 43, Block.stoneBrick.blockID);
		world.setBlock(i + 2, j + 7, k + 45, Block.stoneBrick.blockID);
		world.setBlock(i + 2, j + 7, k + 47, Block.stoneBrick.blockID);
		world.setBlock(i + 2, j + 7, k + 49, Block.stoneBrick.blockID);
		world.setBlock(i + 2, j + 7, k + 51, Block.stoneBrick.blockID);
		world.setBlock(i + 3, j + 0, k + 1, Block.stoneBrick.blockID);
		world.setBlock(i + 3, j + 0, k + 2, Block.glowStone.blockID);
		world.setBlock(i + 3, j + 0, k + 24, Block.glowStone.blockID);
		world.setBlock(i + 3, j + 0, k + 25, Block.stoneBrick.blockID);
		world.setBlock(i + 3, j + 0, k + 26, Block.glowStone.blockID);
		world.setBlock(i + 3, j + 0, k + 50, Block.glowStone.blockID);
		world.setBlock(i + 3, j + 0, k + 51, Block.stoneBrick.blockID);
		world.setBlock(i + 3, j + 1, k + 1, Block.stoneBrick.blockID);
		world.setBlock(i + 3, j + 1, k + 2, Block.glowStone.blockID);
		world.setBlock(i + 3, j + 1, k + 24, Block.glowStone.blockID);
		world.setBlock(i + 3, j + 1, k + 25, Block.stoneBrick.blockID);
		world.setBlock(i + 3, j + 1, k + 26, Block.glowStone.blockID);
		world.setBlock(i + 3, j + 1, k + 50, Block.glowStone.blockID);
		world.setBlock(i + 3, j + 1, k + 51, Block.stoneBrick.blockID);
		world.setBlock(i + 3, j + 2, k + 1, Block.stoneBrick.blockID);
		world.setBlock(i + 3, j + 2, k + 2, Block.glowStone.blockID);
		world.setBlock(i + 3, j + 2, k + 24, Block.glowStone.blockID);
		world.setBlock(i + 3, j + 2, k + 25, Block.stoneBrick.blockID);
		world.setBlock(i + 3, j + 2, k + 26, Block.glowStone.blockID);
		world.setBlock(i + 3, j + 2, k + 50, Block.glowStone.blockID);
		world.setBlock(i + 3, j + 2, k + 51, Block.stoneBrick.blockID);
		world.setBlock(i + 3, j + 3, k + 1, Block.stoneBrick.blockID);
		world.setBlock(i + 3, j + 3, k + 2, Block.glowStone.blockID);
		world.setBlock(i + 3, j + 3, k + 24, Block.glowStone.blockID);
		world.setBlock(i + 3, j + 3, k + 25, Block.stoneBrick.blockID);
		world.setBlock(i + 3, j + 3, k + 26, Block.glowStone.blockID);
		world.setBlock(i + 3, j + 3, k + 50, Block.glowStone.blockID);
		world.setBlock(i + 3, j + 3, k + 51, Block.stoneBrick.blockID);
		world.setBlock(i + 3, j + 4, k + 1, Block.stoneBrick.blockID);
		world.setBlock(i + 3, j + 4, k + 2, Block.glowStone.blockID);
		world.setBlock(i + 3, j + 4, k + 3, Block.glowStone.blockID);
		world.setBlock(i + 3, j + 4, k + 4, Block.glowStone.blockID);
		world.setBlock(i + 3, j + 4, k + 5, Block.glowStone.blockID);
		world.setBlock(i + 3, j + 4, k + 6, Block.glowStone.blockID);
		world.setBlock(i + 3, j + 4, k + 7, Block.glowStone.blockID);
		world.setBlock(i + 3, j + 4, k + 8, Block.glowStone.blockID);
		world.setBlock(i + 3, j + 4, k + 9, Block.glowStone.blockID);
		world.setBlock(i + 3, j + 4, k + 10, Block.glowStone.blockID);
		world.setBlock(i + 3, j + 4, k + 11, Block.glowStone.blockID);
		world.setBlock(i + 3, j + 4, k + 12, Block.glowStone.blockID);
		world.setBlock(i + 3, j + 4, k + 13, Block.glowStone.blockID);
		world.setBlock(i + 3, j + 4, k + 14, Block.glowStone.blockID);
		world.setBlock(i + 3, j + 4, k + 15, Block.glowStone.blockID);
		world.setBlock(i + 3, j + 4, k + 16, Block.glowStone.blockID);
		world.setBlock(i + 3, j + 4, k + 17, Block.glowStone.blockID);
		world.setBlock(i + 3, j + 4, k + 18, Block.glowStone.blockID);
		world.setBlock(i + 3, j + 4, k + 19, Block.glowStone.blockID);
		world.setBlock(i + 3, j + 4, k + 20, Block.glowStone.blockID);
		world.setBlock(i + 3, j + 4, k + 21, Block.glowStone.blockID);
		world.setBlock(i + 3, j + 4, k + 22, Block.glowStone.blockID);
		world.setBlock(i + 3, j + 4, k + 23, Block.glowStone.blockID);
		world.setBlock(i + 3, j + 4, k + 24, Block.glowStone.blockID);
		world.setBlock(i + 3, j + 4, k + 25, Block.glowStone.blockID);
		world.setBlock(i + 3, j + 4, k + 26, Block.glowStone.blockID);
		world.setBlock(i + 3, j + 4, k + 27, Block.glowStone.blockID);
		world.setBlock(i + 3, j + 4, k + 28, Block.glowStone.blockID);
		world.setBlock(i + 3, j + 4, k + 29, Block.glowStone.blockID);
		world.setBlock(i + 3, j + 4, k + 30, Block.glowStone.blockID);
		world.setBlock(i + 3, j + 4, k + 31, Block.glowStone.blockID);
		world.setBlock(i + 3, j + 4, k + 32, Block.glowStone.blockID);
		world.setBlock(i + 3, j + 4, k + 33, Block.glowStone.blockID);
		world.setBlock(i + 3, j + 4, k + 34, Block.glowStone.blockID);
		world.setBlock(i + 3, j + 4, k + 35, Block.glowStone.blockID);
		world.setBlock(i + 3, j + 4, k + 36, Block.glowStone.blockID);
		world.setBlock(i + 3, j + 4, k + 37, Block.glowStone.blockID);
		world.setBlock(i + 3, j + 4, k + 38, Block.glowStone.blockID);
		world.setBlock(i + 3, j + 4, k + 39, Block.glowStone.blockID);
		world.setBlock(i + 3, j + 4, k + 40, Block.glowStone.blockID);
		world.setBlock(i + 3, j + 4, k + 41, Block.glowStone.blockID);
		world.setBlock(i + 3, j + 4, k + 42, Block.glowStone.blockID);
		world.setBlock(i + 3, j + 4, k + 43, Block.glowStone.blockID);
		world.setBlock(i + 3, j + 4, k + 44, Block.glowStone.blockID);
		world.setBlock(i + 3, j + 4, k + 45, Block.glowStone.blockID);
		world.setBlock(i + 3, j + 4, k + 46, Block.glowStone.blockID);
		world.setBlock(i + 3, j + 4, k + 47, Block.glowStone.blockID);
		world.setBlock(i + 3, j + 4, k + 48, Block.glowStone.blockID);
		world.setBlock(i + 3, j + 4, k + 49, Block.glowStone.blockID);
		world.setBlock(i + 3, j + 4, k + 50, Block.glowStone.blockID);
		world.setBlock(i + 3, j + 4, k + 51, Block.stoneBrick.blockID);
		world.setBlock(i + 3, j + 5, k + 1, Block.stoneBrick.blockID);
		world.setBlock(i + 3, j + 5, k + 2, Block.glowStone.blockID);
		world.setBlock(i + 3, j + 5, k + 3, Block.glowStone.blockID);
		world.setBlock(i + 3, j + 5, k + 4, Block.glowStone.blockID);
		world.setBlock(i + 3, j + 5, k + 5, Block.glowStone.blockID);
		world.setBlock(i + 3, j + 5, k + 6, Block.glowStone.blockID);
		world.setBlock(i + 3, j + 5, k + 7, Block.glowStone.blockID);
		world.setBlock(i + 3, j + 5, k + 8, Block.glowStone.blockID);
		world.setBlock(i + 3, j + 5, k + 9, Block.glowStone.blockID);
		world.setBlock(i + 3, j + 5, k + 10, Block.glowStone.blockID);
		world.setBlock(i + 3, j + 5, k + 11, Block.glowStone.blockID);
		world.setBlock(i + 3, j + 5, k + 12, Block.glowStone.blockID);
		world.setBlock(i + 3, j + 5, k + 13, Block.glowStone.blockID);
		world.setBlock(i + 3, j + 5, k + 14, Block.glowStone.blockID);
		world.setBlock(i + 3, j + 5, k + 15, Block.glowStone.blockID);
		world.setBlock(i + 3, j + 5, k + 16, Block.glowStone.blockID);
		world.setBlock(i + 3, j + 5, k + 17, Block.glowStone.blockID);
		world.setBlock(i + 3, j + 5, k + 18, Block.glowStone.blockID);
		world.setBlock(i + 3, j + 5, k + 19, Block.glowStone.blockID);
		world.setBlock(i + 3, j + 5, k + 20, Block.glowStone.blockID);
		world.setBlock(i + 3, j + 5, k + 21, Block.glowStone.blockID);
		world.setBlock(i + 3, j + 5, k + 22, Block.glowStone.blockID);
		world.setBlock(i + 3, j + 5, k + 23, Block.glowStone.blockID);
		world.setBlock(i + 3, j + 5, k + 24, Block.glowStone.blockID);
		world.setBlock(i + 3, j + 5, k + 25, Block.glowStone.blockID);
		world.setBlock(i + 3, j + 5, k + 26, Block.glowStone.blockID);
		world.setBlock(i + 3, j + 5, k + 27, Block.glowStone.blockID);
		world.setBlock(i + 3, j + 5, k + 28, Block.glowStone.blockID);
		world.setBlock(i + 3, j + 5, k + 29, Block.glowStone.blockID);
		world.setBlock(i + 3, j + 5, k + 30, Block.glowStone.blockID);
		world.setBlock(i + 3, j + 5, k + 31, Block.glowStone.blockID);
		world.setBlock(i + 3, j + 5, k + 32, Block.glowStone.blockID);
		world.setBlock(i + 3, j + 5, k + 33, Block.glowStone.blockID);
		world.setBlock(i + 3, j + 5, k + 34, Block.glowStone.blockID);
		world.setBlock(i + 3, j + 5, k + 35, Block.glowStone.blockID);
		world.setBlock(i + 3, j + 5, k + 36, Block.glowStone.blockID);
		world.setBlock(i + 3, j + 5, k + 37, Block.glowStone.blockID);
		world.setBlock(i + 3, j + 5, k + 38, Block.glowStone.blockID);
		world.setBlock(i + 3, j + 5, k + 39, Block.glowStone.blockID);
		world.setBlock(i + 3, j + 5, k + 40, Block.glowStone.blockID);
		world.setBlock(i + 3, j + 5, k + 41, Block.glowStone.blockID);
		world.setBlock(i + 3, j + 5, k + 42, Block.glowStone.blockID);
		world.setBlock(i + 3, j + 5, k + 43, Block.glowStone.blockID);
		world.setBlock(i + 3, j + 5, k + 44, Block.glowStone.blockID);
		world.setBlock(i + 3, j + 5, k + 45, Block.glowStone.blockID);
		world.setBlock(i + 3, j + 5, k + 46, Block.glowStone.blockID);
		world.setBlock(i + 3, j + 5, k + 47, Block.glowStone.blockID);
		world.setBlock(i + 3, j + 5, k + 48, Block.glowStone.blockID);
		world.setBlock(i + 3, j + 5, k + 49, Block.glowStone.blockID);
		world.setBlock(i + 3, j + 5, k + 50, Block.glowStone.blockID);
		world.setBlock(i + 3, j + 5, k + 51, Block.stoneBrick.blockID);
		world.setBlock(i + 3, j + 6, k + 1, Block.stoneBrick.blockID);
		world.setBlock(i + 3, j + 6, k + 51, Block.stoneBrick.blockID);
		world.setBlock(i + 4, j + 0, k + 1, Block.stoneBrick.blockID);
		world.setBlock(i + 4, j + 0, k + 25, Block.stoneBrick.blockID);
		world.setBlock(i + 4, j + 0, k + 51, Block.stoneBrick.blockID);
		world.setBlock(i + 4, j + 1, k + 1, Block.stoneBrick.blockID);
		world.setBlock(i + 4, j + 1, k + 25, Block.stoneBrick.blockID);
		world.setBlock(i + 4, j + 1, k + 51, Block.stoneBrick.blockID);
		world.setBlock(i + 4, j + 2, k + 1, Block.stoneBrick.blockID);
		world.setBlock(i + 4, j + 2, k + 25, Block.stoneBrick.blockID);
		world.setBlock(i + 4, j + 2, k + 51, Block.stoneBrick.blockID);
		world.setBlock(i + 4, j + 3, k + 1, Block.stoneBrick.blockID);
		world.setBlock(i + 4, j + 3, k + 25, Block.stoneBrick.blockID);
		world.setBlock(i + 4, j + 3, k + 51, Block.stoneBrick.blockID);
		world.setBlock(i + 4, j + 4, k + 1, Block.stoneBrick.blockID);
		world.setBlock(i + 4, j + 4, k + 2, Block.glowStone.blockID);
		world.setBlock(i + 4, j + 4, k + 24, Block.glowStone.blockID);
		world.setBlock(i + 4, j + 4, k + 25, Block.stoneBrick.blockID);
		world.setBlock(i + 4, j + 4, k + 50, Block.glowStone.blockID);
		world.setBlock(i + 4, j + 4, k + 51, Block.stoneBrick.blockID);
		world.setBlock(i + 4, j + 5, k + 1, Block.stoneBrick.blockID);
		world.setBlock(i + 4, j + 5, k + 2, Block.glowStone.blockID);
		world.setBlock(i + 4, j + 5, k + 3, Block.stoneBrick.blockID);
		world.setBlock(i + 4, j + 5, k + 4, Block.stoneBrick.blockID);
		world.setBlock(i + 4, j + 5, k + 5, Block.stoneBrick.blockID);
		world.setBlock(i + 4, j + 5, k + 6, Block.stoneBrick.blockID);
		world.setBlock(i + 4, j + 5, k + 7, Block.stoneBrick.blockID);
		world.setBlock(i + 4, j + 5, k + 8, Block.stoneBrick.blockID);
		world.setBlock(i + 4, j + 5, k + 9, Block.stoneBrick.blockID);
		world.setBlock(i + 4, j + 5, k + 10, Block.stoneBrick.blockID);
		world.setBlock(i + 4, j + 5, k + 11, Block.stoneBrick.blockID);
		world.setBlock(i + 4, j + 5, k + 12, Block.stoneBrick.blockID);
		world.setBlock(i + 4, j + 5, k + 13, Block.stoneBrick.blockID);
		world.setBlock(i + 4, j + 5, k + 14, Block.stoneBrick.blockID);
		world.setBlock(i + 4, j + 5, k + 15, Block.stoneBrick.blockID);
		world.setBlock(i + 4, j + 5, k + 16, Block.stoneBrick.blockID);
		world.setBlock(i + 4, j + 5, k + 17, Block.stoneBrick.blockID);
		world.setBlock(i + 4, j + 5, k + 18, Block.stoneBrick.blockID);
		world.setBlock(i + 4, j + 5, k + 19, Block.stoneBrick.blockID);
		world.setBlock(i + 4, j + 5, k + 20, Block.stoneBrick.blockID);
		world.setBlock(i + 4, j + 5, k + 21, Block.stoneBrick.blockID);
		world.setBlock(i + 4, j + 5, k + 22, Block.stoneBrick.blockID);
		world.setBlock(i + 4, j + 5, k + 23, Block.stoneBrick.blockID);
		world.setBlock(i + 4, j + 5, k + 24, Block.stoneBrick.blockID);
		world.setBlock(i + 4, j + 5, k + 25, Block.stoneBrick.blockID);
		world.setBlock(i + 4, j + 5, k + 26, Block.stoneBrick.blockID);
		world.setBlock(i + 4, j + 5, k + 27, Block.stoneBrick.blockID);
		world.setBlock(i + 4, j + 5, k + 28, Block.stoneBrick.blockID);
		world.setBlock(i + 4, j + 5, k + 29, Block.stoneBrick.blockID);
		world.setBlock(i + 4, j + 5, k + 30, Block.stoneBrick.blockID);
		world.setBlock(i + 4, j + 5, k + 31, Block.stoneBrick.blockID);
		world.setBlock(i + 4, j + 5, k + 32, Block.stoneBrick.blockID);
		world.setBlock(i + 4, j + 5, k + 33, Block.stoneBrick.blockID);
		world.setBlock(i + 4, j + 5, k + 34, Block.stoneBrick.blockID);
		world.setBlock(i + 4, j + 5, k + 35, Block.stoneBrick.blockID);
		world.setBlock(i + 4, j + 5, k + 36, Block.stoneBrick.blockID);
		world.setBlock(i + 4, j + 5, k + 37, Block.stoneBrick.blockID);
		world.setBlock(i + 4, j + 5, k + 38, Block.stoneBrick.blockID);
		world.setBlock(i + 4, j + 5, k + 39, Block.stoneBrick.blockID);
		world.setBlock(i + 4, j + 5, k + 40, Block.stoneBrick.blockID);
		world.setBlock(i + 4, j + 5, k + 41, Block.stoneBrick.blockID);
		world.setBlock(i + 4, j + 5, k + 42, Block.stoneBrick.blockID);
		world.setBlock(i + 4, j + 5, k + 43, Block.stoneBrick.blockID);
		world.setBlock(i + 4, j + 5, k + 44, Block.stoneBrick.blockID);
		world.setBlock(i + 4, j + 5, k + 45, Block.stoneBrick.blockID);
		world.setBlock(i + 4, j + 5, k + 46, Block.stoneBrick.blockID);
		world.setBlock(i + 4, j + 5, k + 47, Block.stoneBrick.blockID);
		world.setBlock(i + 4, j + 5, k + 48, Block.stoneBrick.blockID);
		world.setBlock(i + 4, j + 5, k + 49, Block.stoneBrick.blockID);
		world.setBlock(i + 4, j + 5, k + 50, Block.glowStone.blockID);
		world.setBlock(i + 4, j + 5, k + 51, Block.stoneBrick.blockID);
		world.setBlock(i + 4, j + 6, k + 1, Block.stoneBrick.blockID);
		world.setBlock(i + 4, j + 6, k + 51, Block.stoneBrick.blockID);
		world.setBlock(i + 4, j + 7, k + 1, Block.stoneBrick.blockID);
		world.setBlock(i + 4, j + 7, k + 51, Block.stoneBrick.blockID);
		world.setBlock(i + 5, j + 0, k + 1, Block.stoneBrick.blockID);
		world.setBlock(i + 5, j + 0, k + 25, Block.stoneBrick.blockID);
		world.setBlock(i + 5, j + 0, k + 51, Block.stoneBrick.blockID);
		world.setBlock(i + 5, j + 1, k + 1, Block.stoneBrick.blockID);
		world.setBlock(i + 5, j + 1, k + 25, Block.stoneBrick.blockID);
		world.setBlock(i + 5, j + 1, k + 51, Block.stoneBrick.blockID);
		world.setBlock(i + 5, j + 2, k + 1, Block.stoneBrick.blockID);
		world.setBlock(i + 5, j + 2, k + 25, Block.stoneBrick.blockID);
		world.setBlock(i + 5, j + 2, k + 51, Block.stoneBrick.blockID);
		world.setBlock(i + 5, j + 3, k + 1, Block.stoneBrick.blockID);
		world.setBlock(i + 5, j + 3, k + 25, Block.stoneBrick.blockID);
		world.setBlock(i + 5, j + 3, k + 51, Block.stoneBrick.blockID);
		world.setBlock(i + 5, j + 4, k + 1, Block.stoneBrick.blockID);
		world.setBlock(i + 5, j + 4, k + 2, Block.glowStone.blockID);
		world.setBlock(i + 5, j + 4, k + 24, Block.glowStone.blockID);
		world.setBlock(i + 5, j + 4, k + 25, Block.stoneBrick.blockID);
		world.setBlock(i + 5, j + 4, k + 50, Block.glowStone.blockID);
		world.setBlock(i + 5, j + 4, k + 51, Block.stoneBrick.blockID);
		world.setBlock(i + 5, j + 5, k + 1, Block.stoneBrick.blockID);
		world.setBlock(i + 5, j + 5, k + 2, Block.glowStone.blockID);
		world.setBlock(i + 5, j + 5, k + 3, Block.stoneBrick.blockID);
		world.setBlock(i + 5, j + 5, k + 4, Block.stoneBrick.blockID);
		world.setBlock(i + 5, j + 5, k + 5, Block.stoneBrick.blockID);
		world.setBlock(i + 5, j + 5, k + 6, Block.stoneBrick.blockID);
		world.setBlock(i + 5, j + 5, k + 7, Block.stoneBrick.blockID);
		world.setBlock(i + 5, j + 5, k + 8, Block.stoneBrick.blockID);
		world.setBlock(i + 5, j + 5, k + 9, Block.stoneBrick.blockID);
		world.setBlock(i + 5, j + 5, k + 10, Block.stoneBrick.blockID);
		world.setBlock(i + 5, j + 5, k + 11, Block.stoneBrick.blockID);
		world.setBlock(i + 5, j + 5, k + 12, Block.stoneBrick.blockID);
		world.setBlock(i + 5, j + 5, k + 13, Block.stoneBrick.blockID);
		world.setBlock(i + 5, j + 5, k + 14, Block.stoneBrick.blockID);
		world.setBlock(i + 5, j + 5, k + 15, Block.stoneBrick.blockID);
		world.setBlock(i + 5, j + 5, k + 16, Block.stoneBrick.blockID);
		world.setBlock(i + 5, j + 5, k + 17, Block.stoneBrick.blockID);
		world.setBlock(i + 5, j + 5, k + 18, Block.stoneBrick.blockID);
		world.setBlock(i + 5, j + 5, k + 19, Block.stoneBrick.blockID);
		world.setBlock(i + 5, j + 5, k + 20, Block.stoneBrick.blockID);
		world.setBlock(i + 5, j + 5, k + 21, Block.stoneBrick.blockID);
		world.setBlock(i + 5, j + 5, k + 22, Block.stoneBrick.blockID);
		world.setBlock(i + 5, j + 5, k + 23, Block.stoneBrick.blockID);
		world.setBlock(i + 5, j + 5, k + 24, Block.stoneBrick.blockID);
		world.setBlock(i + 5, j + 5, k + 25, Block.stoneBrick.blockID);
		world.setBlock(i + 5, j + 5, k + 26, Block.stoneBrick.blockID);
		world.setBlock(i + 5, j + 5, k + 27, Block.stoneBrick.blockID);
		world.setBlock(i + 5, j + 5, k + 28, Block.stoneBrick.blockID);
		world.setBlock(i + 5, j + 5, k + 29, Block.stoneBrick.blockID);
		world.setBlock(i + 5, j + 5, k + 30, Block.stoneBrick.blockID);
		world.setBlock(i + 5, j + 5, k + 31, Block.stoneBrick.blockID);
		world.setBlock(i + 5, j + 5, k + 32, Block.stoneBrick.blockID);
		world.setBlock(i + 5, j + 5, k + 33, Block.stoneBrick.blockID);
		world.setBlock(i + 5, j + 5, k + 34, Block.stoneBrick.blockID);
		world.setBlock(i + 5, j + 5, k + 35, Block.stoneBrick.blockID);
		world.setBlock(i + 5, j + 5, k + 36, Block.stoneBrick.blockID);
		world.setBlock(i + 5, j + 5, k + 37, Block.stoneBrick.blockID);
		world.setBlock(i + 5, j + 5, k + 38, Block.stoneBrick.blockID);
		world.setBlock(i + 5, j + 5, k + 39, Block.stoneBrick.blockID);
		world.setBlock(i + 5, j + 5, k + 40, Block.stoneBrick.blockID);
		world.setBlock(i + 5, j + 5, k + 41, Block.stoneBrick.blockID);
		world.setBlock(i + 5, j + 5, k + 42, Block.stoneBrick.blockID);
		world.setBlock(i + 5, j + 5, k + 43, Block.stoneBrick.blockID);
		world.setBlock(i + 5, j + 5, k + 44, Block.stoneBrick.blockID);
		world.setBlock(i + 5, j + 5, k + 45, Block.stoneBrick.blockID);
		world.setBlock(i + 5, j + 5, k + 46, Block.stoneBrick.blockID);
		world.setBlock(i + 5, j + 5, k + 47, Block.stoneBrick.blockID);
		world.setBlock(i + 5, j + 5, k + 48, Block.stoneBrick.blockID);
		world.setBlock(i + 5, j + 5, k + 49, Block.stoneBrick.blockID);
		world.setBlock(i + 5, j + 5, k + 50, Block.glowStone.blockID);
		world.setBlock(i + 5, j + 5, k + 51, Block.stoneBrick.blockID);
		world.setBlock(i + 5, j + 6, k + 1, Block.stoneBrick.blockID);
		world.setBlock(i + 5, j + 6, k + 51, Block.stoneBrick.blockID);
		world.setBlock(i + 6, j + 0, k + 1, Block.stoneBrick.blockID);
		world.setBlock(i + 6, j + 0, k + 25, Block.stoneBrick.blockID);
		world.setBlock(i + 6, j + 0, k + 51, Block.stoneBrick.blockID);
		world.setBlock(i + 6, j + 1, k + 1, Block.stoneBrick.blockID);
		world.setBlock(i + 6, j + 1, k + 25, Block.stoneBrick.blockID);
		world.setBlock(i + 6, j + 1, k + 51, Block.stoneBrick.blockID);
		world.setBlock(i + 6, j + 2, k + 1, Block.stoneBrick.blockID);
		world.setBlock(i + 6, j + 2, k + 25, Block.stoneBrick.blockID);
		world.setBlock(i + 6, j + 2, k + 51, Block.stoneBrick.blockID);
		world.setBlock(i + 6, j + 3, k + 1, Block.stoneBrick.blockID);
		world.setBlock(i + 6, j + 3, k + 25, Block.stoneBrick.blockID);
		world.setBlock(i + 6, j + 3, k + 51, Block.stoneBrick.blockID);
		world.setBlock(i + 6, j + 4, k + 1, Block.stoneBrick.blockID);
		world.setBlock(i + 6, j + 4, k + 2, Block.glowStone.blockID);
		world.setBlock(i + 6, j + 4, k + 24, Block.glowStone.blockID);
		world.setBlock(i + 6, j + 4, k + 25, Block.stoneBrick.blockID);
		world.setBlock(i + 6, j + 4, k + 50, Block.glowStone.blockID);
		world.setBlock(i + 6, j + 4, k + 51, Block.stoneBrick.blockID);
		world.setBlock(i + 6, j + 5, k + 1, Block.stoneBrick.blockID);
		world.setBlock(i + 6, j + 5, k + 2, Block.glowStone.blockID);
		world.setBlock(i + 6, j + 5, k + 3, Block.stoneBrick.blockID);
		world.setBlock(i + 6, j + 5, k + 4, Block.stoneBrick.blockID);
		world.setBlock(i + 6, j + 5, k + 5, Block.stoneBrick.blockID);
		world.setBlock(i + 6, j + 5, k + 6, Block.stoneBrick.blockID);
		world.setBlock(i + 6, j + 5, k + 7, Block.stoneBrick.blockID);
		world.setBlock(i + 6, j + 5, k + 8, Block.stoneBrick.blockID);
		world.setBlock(i + 6, j + 5, k + 9, Block.stoneBrick.blockID);
		world.setBlock(i + 6, j + 5, k + 10, Block.stoneBrick.blockID);
		world.setBlock(i + 6, j + 5, k + 11, Block.stoneBrick.blockID);
		world.setBlock(i + 6, j + 5, k + 12, Block.stoneBrick.blockID);
		world.setBlock(i + 6, j + 5, k + 13, Block.stoneBrick.blockID);
		world.setBlock(i + 6, j + 5, k + 14, Block.stoneBrick.blockID);
		world.setBlock(i + 6, j + 5, k + 15, Block.stoneBrick.blockID);
		world.setBlock(i + 6, j + 5, k + 16, Block.stoneBrick.blockID);
		world.setBlock(i + 6, j + 5, k + 17, Block.stoneBrick.blockID);
		world.setBlock(i + 6, j + 5, k + 18, Block.stoneBrick.blockID);
		world.setBlock(i + 6, j + 5, k + 19, Block.stoneBrick.blockID);
		world.setBlock(i + 6, j + 5, k + 20, Block.stoneBrick.blockID);
		world.setBlock(i + 6, j + 5, k + 21, Block.stoneBrick.blockID);
		world.setBlock(i + 6, j + 5, k + 22, Block.stoneBrick.blockID);
		world.setBlock(i + 6, j + 5, k + 23, Block.stoneBrick.blockID);
		world.setBlock(i + 6, j + 5, k + 24, Block.stoneBrick.blockID);
		world.setBlock(i + 6, j + 5, k + 25, Block.stoneBrick.blockID);
		world.setBlock(i + 6, j + 5, k + 26, Block.stoneBrick.blockID);
		world.setBlock(i + 6, j + 5, k + 27, Block.stoneBrick.blockID);
		world.setBlock(i + 6, j + 5, k + 28, Block.stoneBrick.blockID);
		world.setBlock(i + 6, j + 5, k + 29, Block.stoneBrick.blockID);
		world.setBlock(i + 6, j + 5, k + 30, Block.stoneBrick.blockID);
		world.setBlock(i + 6, j + 5, k + 31, Block.stoneBrick.blockID);
		world.setBlock(i + 6, j + 5, k + 32, Block.stoneBrick.blockID);
		world.setBlock(i + 6, j + 5, k + 33, Block.stoneBrick.blockID);
		world.setBlock(i + 6, j + 5, k + 34, Block.stoneBrick.blockID);
		world.setBlock(i + 6, j + 5, k + 35, Block.stoneBrick.blockID);
		world.setBlock(i + 6, j + 5, k + 36, Block.stoneBrick.blockID);
		world.setBlock(i + 6, j + 5, k + 37, Block.stoneBrick.blockID);
		world.setBlock(i + 6, j + 5, k + 38, Block.stoneBrick.blockID);
		world.setBlock(i + 6, j + 5, k + 39, Block.stoneBrick.blockID);
		world.setBlock(i + 6, j + 5, k + 40, Block.stoneBrick.blockID);
		world.setBlock(i + 6, j + 5, k + 41, Block.stoneBrick.blockID);
		world.setBlock(i + 6, j + 5, k + 42, Block.stoneBrick.blockID);
		world.setBlock(i + 6, j + 5, k + 43, Block.stoneBrick.blockID);
		world.setBlock(i + 6, j + 5, k + 44, Block.stoneBrick.blockID);
		world.setBlock(i + 6, j + 5, k + 45, Block.stoneBrick.blockID);
		world.setBlock(i + 6, j + 5, k + 46, Block.stoneBrick.blockID);
		world.setBlock(i + 6, j + 5, k + 47, Block.stoneBrick.blockID);
		world.setBlock(i + 6, j + 5, k + 48, Block.stoneBrick.blockID);
		world.setBlock(i + 6, j + 5, k + 49, Block.stoneBrick.blockID);
		world.setBlock(i + 6, j + 5, k + 50, Block.glowStone.blockID);
		world.setBlock(i + 6, j + 5, k + 51, Block.stoneBrick.blockID);
		world.setBlock(i + 6, j + 6, k + 1, Block.stoneBrick.blockID);
		world.setBlock(i + 6, j + 6, k + 51, Block.stoneBrick.blockID);
		world.setBlock(i + 6, j + 7, k + 1, Block.stoneBrick.blockID);
		world.setBlock(i + 6, j + 7, k + 51, Block.stoneBrick.blockID);
		world.setBlock(i + 7, j + 0, k + 1, Block.stoneBrick.blockID);
		world.setBlock(i + 7, j + 0, k + 25, Block.stoneBrick.blockID);
		world.setBlock(i + 7, j + 0, k + 51, Block.stoneBrick.blockID);
		world.setBlock(i + 7, j + 1, k + 1, Block.stoneBrick.blockID);
		world.setBlock(i + 7, j + 1, k + 25, Block.stoneBrick.blockID);
		world.setBlock(i + 7, j + 1, k + 51, Block.stoneBrick.blockID);
		world.setBlock(i + 7, j + 2, k + 1, Block.stoneBrick.blockID);
		world.setBlock(i + 7, j + 2, k + 25, Block.stoneBrick.blockID);
		world.setBlock(i + 7, j + 2, k + 51, Block.stoneBrick.blockID);
		world.setBlock(i + 7, j + 3, k + 1, Block.stoneBrick.blockID);
		world.setBlock(i + 7, j + 3, k + 25, Block.stoneBrick.blockID);
		world.setBlock(i + 7, j + 3, k + 51, Block.stoneBrick.blockID);
		world.setBlock(i + 7, j + 4, k + 1, Block.stoneBrick.blockID);
		world.setBlock(i + 7, j + 4, k + 2, Block.glowStone.blockID);
		world.setBlock(i + 7, j + 4, k + 24, Block.glowStone.blockID);
		world.setBlock(i + 7, j + 4, k + 25, Block.stoneBrick.blockID);
		world.setBlock(i + 7, j + 4, k + 50, Block.glowStone.blockID);
		world.setBlock(i + 7, j + 4, k + 51, Block.stoneBrick.blockID);
		world.setBlock(i + 7, j + 5, k + 1, Block.stoneBrick.blockID);
		world.setBlock(i + 7, j + 5, k + 2, Block.glowStone.blockID);
		world.setBlock(i + 7, j + 5, k + 3, Block.stoneBrick.blockID);
		world.setBlock(i + 7, j + 5, k + 4, Block.stoneBrick.blockID);
		world.setBlock(i + 7, j + 5, k + 5, Block.stoneBrick.blockID);
		world.setBlock(i + 7, j + 5, k + 6, Block.stoneBrick.blockID);
		world.setBlock(i + 7, j + 5, k + 7, Block.stoneBrick.blockID);
		world.setBlock(i + 7, j + 5, k + 8, Block.stoneBrick.blockID);
		world.setBlock(i + 7, j + 5, k + 9, Block.stoneBrick.blockID);
		world.setBlock(i + 7, j + 5, k + 10, Block.stoneBrick.blockID);
		world.setBlock(i + 7, j + 5, k + 11, Block.stoneBrick.blockID);
		world.setBlock(i + 7, j + 5, k + 12, Block.stoneBrick.blockID);
		world.setBlock(i + 7, j + 5, k + 13, Block.stoneBrick.blockID);
		world.setBlock(i + 7, j + 5, k + 14, Block.stoneBrick.blockID);
		world.setBlock(i + 7, j + 5, k + 15, Block.stoneBrick.blockID);
		world.setBlock(i + 7, j + 5, k + 16, Block.stoneBrick.blockID);
		world.setBlock(i + 7, j + 5, k + 17, Block.stoneBrick.blockID);
		world.setBlock(i + 7, j + 5, k + 18, Block.stoneBrick.blockID);
		world.setBlock(i + 7, j + 5, k + 19, Block.stoneBrick.blockID);
		world.setBlock(i + 7, j + 5, k + 20, Block.stoneBrick.blockID);
		world.setBlock(i + 7, j + 5, k + 21, Block.stoneBrick.blockID);
		world.setBlock(i + 7, j + 5, k + 22, Block.stoneBrick.blockID);
		world.setBlock(i + 7, j + 5, k + 23, Block.stoneBrick.blockID);
		world.setBlock(i + 7, j + 5, k + 24, Block.stoneBrick.blockID);
		world.setBlock(i + 7, j + 5, k + 25, Block.stoneBrick.blockID);
		world.setBlock(i + 7, j + 5, k + 26, Block.stoneBrick.blockID);
		world.setBlock(i + 7, j + 5, k + 27, Block.stoneBrick.blockID);
		world.setBlock(i + 7, j + 5, k + 28, Block.stoneBrick.blockID);
		world.setBlock(i + 7, j + 5, k + 29, Block.stoneBrick.blockID);
		world.setBlock(i + 7, j + 5, k + 30, Block.stoneBrick.blockID);
		world.setBlock(i + 7, j + 5, k + 31, Block.stoneBrick.blockID);
		world.setBlock(i + 7, j + 5, k + 32, Block.stoneBrick.blockID);
		world.setBlock(i + 7, j + 5, k + 33, Block.stoneBrick.blockID);
		world.setBlock(i + 7, j + 5, k + 34, Block.stoneBrick.blockID);
		world.setBlock(i + 7, j + 5, k + 35, Block.stoneBrick.blockID);
		world.setBlock(i + 7, j + 5, k + 36, Block.stoneBrick.blockID);
		world.setBlock(i + 7, j + 5, k + 37, Block.stoneBrick.blockID);
		world.setBlock(i + 7, j + 5, k + 38, Block.stoneBrick.blockID);
		world.setBlock(i + 7, j + 5, k + 39, Block.stoneBrick.blockID);
		world.setBlock(i + 7, j + 5, k + 40, Block.stoneBrick.blockID);
		world.setBlock(i + 7, j + 5, k + 41, Block.stoneBrick.blockID);
		world.setBlock(i + 7, j + 5, k + 42, Block.stoneBrick.blockID);
		world.setBlock(i + 7, j + 5, k + 43, Block.stoneBrick.blockID);
		world.setBlock(i + 7, j + 5, k + 44, Block.stoneBrick.blockID);
		world.setBlock(i + 7, j + 5, k + 45, Block.stoneBrick.blockID);
		world.setBlock(i + 7, j + 5, k + 46, Block.stoneBrick.blockID);
		world.setBlock(i + 7, j + 5, k + 47, Block.stoneBrick.blockID);
		world.setBlock(i + 7, j + 5, k + 48, Block.stoneBrick.blockID);
		world.setBlock(i + 7, j + 5, k + 49, Block.stoneBrick.blockID);
		world.setBlock(i + 7, j + 5, k + 50, Block.glowStone.blockID);
		world.setBlock(i + 7, j + 5, k + 51, Block.stoneBrick.blockID);
		world.setBlock(i + 7, j + 6, k + 1, Block.stoneBrick.blockID);
		world.setBlock(i + 7, j + 6, k + 51, Block.stoneBrick.blockID);
		world.setBlock(i + 8, j + 0, k + 1, Block.stoneBrick.blockID);
		world.setBlock(i + 8, j + 0, k + 25, Block.stoneBrick.blockID);
		world.setBlock(i + 8, j + 0, k + 51, Block.stoneBrick.blockID);
		world.setBlock(i + 8, j + 1, k + 1, Block.stoneBrick.blockID);
		world.setBlock(i + 8, j + 1, k + 25, Block.stoneBrick.blockID);
		world.setBlock(i + 8, j + 1, k + 51, Block.stoneBrick.blockID);
		world.setBlock(i + 8, j + 2, k + 1, Block.stoneBrick.blockID);
		world.setBlock(i + 8, j + 2, k + 25, Block.stoneBrick.blockID);
		world.setBlock(i + 8, j + 2, k + 51, Block.stoneBrick.blockID);
		world.setBlock(i + 8, j + 3, k + 1, Block.stoneBrick.blockID);
		world.setBlock(i + 8, j + 3, k + 25, Block.stoneBrick.blockID);
		world.setBlock(i + 8, j + 3, k + 51, Block.stoneBrick.blockID);
		world.setBlock(i + 8, j + 4, k + 1, Block.stoneBrick.blockID);
		world.setBlock(i + 8, j + 4, k + 2, Block.glowStone.blockID);
		world.setBlock(i + 8, j + 4, k + 24, Block.glowStone.blockID);
		world.setBlock(i + 8, j + 4, k + 25, Block.stoneBrick.blockID);
		world.setBlock(i + 8, j + 4, k + 50, Block.glowStone.blockID);
		world.setBlock(i + 8, j + 4, k + 51, Block.stoneBrick.blockID);
		world.setBlock(i + 8, j + 5, k + 1, Block.stoneBrick.blockID);
		world.setBlock(i + 8, j + 5, k + 2, Block.glowStone.blockID);
		world.setBlock(i + 8, j + 5, k + 3, Block.stoneBrick.blockID);
		world.setBlock(i + 8, j + 5, k + 4, Block.stoneBrick.blockID);
		world.setBlock(i + 8, j + 5, k + 5, Block.stoneBrick.blockID);
		world.setBlock(i + 8, j + 5, k + 6, Block.stoneBrick.blockID);
		world.setBlock(i + 8, j + 5, k + 7, Block.stoneBrick.blockID);
		world.setBlock(i + 8, j + 5, k + 8, Block.stoneBrick.blockID);
		world.setBlock(i + 8, j + 5, k + 9, Block.stoneBrick.blockID);
		world.setBlock(i + 8, j + 5, k + 10, Block.stoneBrick.blockID);
		world.setBlock(i + 8, j + 5, k + 11, Block.stoneBrick.blockID);
		world.setBlock(i + 8, j + 5, k + 12, Block.stoneBrick.blockID);
		world.setBlock(i + 8, j + 5, k + 13, Block.stoneBrick.blockID);
		world.setBlock(i + 8, j + 5, k + 14, Block.stoneBrick.blockID);
		world.setBlock(i + 8, j + 5, k + 15, Block.stoneBrick.blockID);
		world.setBlock(i + 8, j + 5, k + 16, Block.stoneBrick.blockID);
		world.setBlock(i + 8, j + 5, k + 17, Block.stoneBrick.blockID);
		world.setBlock(i + 8, j + 5, k + 18, Block.stoneBrick.blockID);
		world.setBlock(i + 8, j + 5, k + 19, Block.stoneBrick.blockID);
		world.setBlock(i + 8, j + 5, k + 20, Block.stoneBrick.blockID);
		world.setBlock(i + 8, j + 5, k + 21, Block.stoneBrick.blockID);
		world.setBlock(i + 8, j + 5, k + 22, Block.stoneBrick.blockID);
		world.setBlock(i + 8, j + 5, k + 23, Block.stoneBrick.blockID);
		world.setBlock(i + 8, j + 5, k + 24, Block.stoneBrick.blockID);
		world.setBlock(i + 8, j + 5, k + 25, Block.stoneBrick.blockID);
		world.setBlock(i + 8, j + 5, k + 26, Block.stoneBrick.blockID);
		world.setBlock(i + 8, j + 5, k + 27, Block.stoneBrick.blockID);
		world.setBlock(i + 8, j + 5, k + 28, Block.stoneBrick.blockID);
		world.setBlock(i + 8, j + 5, k + 29, Block.stoneBrick.blockID);
		world.setBlock(i + 8, j + 5, k + 30, Block.stoneBrick.blockID);
		world.setBlock(i + 8, j + 5, k + 31, Block.stoneBrick.blockID);
		world.setBlock(i + 8, j + 5, k + 32, Block.stoneBrick.blockID);
		world.setBlock(i + 8, j + 5, k + 33, Block.stoneBrick.blockID);
		world.setBlock(i + 8, j + 5, k + 34, Block.stoneBrick.blockID);
		world.setBlock(i + 8, j + 5, k + 35, Block.stoneBrick.blockID);
		world.setBlock(i + 8, j + 5, k + 36, Block.stoneBrick.blockID);
		world.setBlock(i + 8, j + 5, k + 37, Block.stoneBrick.blockID);
		world.setBlock(i + 8, j + 5, k + 38, Block.stoneBrick.blockID);
		world.setBlock(i + 8, j + 5, k + 39, Block.stoneBrick.blockID);
		world.setBlock(i + 8, j + 5, k + 40, Block.stoneBrick.blockID);
		world.setBlock(i + 8, j + 5, k + 41, Block.stoneBrick.blockID);
		world.setBlock(i + 8, j + 5, k + 42, Block.stoneBrick.blockID);
		world.setBlock(i + 8, j + 5, k + 43, Block.stoneBrick.blockID);
		world.setBlock(i + 8, j + 5, k + 44, Block.stoneBrick.blockID);
		world.setBlock(i + 8, j + 5, k + 45, Block.stoneBrick.blockID);
		world.setBlock(i + 8, j + 5, k + 46, Block.stoneBrick.blockID);
		world.setBlock(i + 8, j + 5, k + 47, Block.stoneBrick.blockID);
		world.setBlock(i + 8, j + 5, k + 48, Block.stoneBrick.blockID);
		world.setBlock(i + 8, j + 5, k + 49, Block.stoneBrick.blockID);
		world.setBlock(i + 8, j + 5, k + 50, Block.glowStone.blockID);
		world.setBlock(i + 8, j + 5, k + 51, Block.stoneBrick.blockID);
		world.setBlock(i + 8, j + 6, k + 1, Block.stoneBrick.blockID);
		world.setBlock(i + 8, j + 6, k + 51, Block.stoneBrick.blockID);
		world.setBlock(i + 8, j + 7, k + 1, Block.stoneBrick.blockID);
		world.setBlock(i + 8, j + 7, k + 51, Block.stoneBrick.blockID);
		world.setBlock(i + 9, j + 0, k + 1, Block.stoneBrick.blockID);
		world.setBlock(i + 9, j + 0, k + 25, Block.stoneBrick.blockID);
		world.setBlock(i + 9, j + 0, k + 51, Block.stoneBrick.blockID);
		world.setBlock(i + 9, j + 1, k + 1, Block.stoneBrick.blockID);
		world.setBlock(i + 9, j + 1, k + 25, Block.stoneBrick.blockID);
		world.setBlock(i + 9, j + 1, k + 51, Block.stoneBrick.blockID);
		world.setBlock(i + 9, j + 2, k + 1, Block.stoneBrick.blockID);
		world.setBlock(i + 9, j + 2, k + 25, Block.stoneBrick.blockID);
		world.setBlock(i + 9, j + 2, k + 51, Block.stoneBrick.blockID);
		world.setBlock(i + 9, j + 3, k + 1, Block.stoneBrick.blockID);
		world.setBlock(i + 9, j + 3, k + 25, Block.stoneBrick.blockID);
		world.setBlock(i + 9, j + 3, k + 51, Block.stoneBrick.blockID);
		world.setBlock(i + 9, j + 4, k + 1, Block.stoneBrick.blockID);
		world.setBlock(i + 9, j + 4, k + 2, Block.glowStone.blockID);
		world.setBlock(i + 9, j + 4, k + 24, Block.glowStone.blockID);
		world.setBlock(i + 9, j + 4, k + 25, Block.stoneBrick.blockID);
		world.setBlock(i + 9, j + 4, k + 50, Block.glowStone.blockID);
		world.setBlock(i + 9, j + 4, k + 51, Block.stoneBrick.blockID);
		world.setBlock(i + 9, j + 5, k + 1, Block.stoneBrick.blockID);
		world.setBlock(i + 9, j + 5, k + 2, Block.glowStone.blockID);
		world.setBlock(i + 9, j + 5, k + 3, Block.stoneBrick.blockID);
		world.setBlock(i + 9, j + 5, k + 4, Block.stoneBrick.blockID);
		world.setBlock(i + 9, j + 5, k + 5, Block.stoneBrick.blockID);
		world.setBlock(i + 9, j + 5, k + 6, Block.stoneBrick.blockID);
		world.setBlock(i + 9, j + 5, k + 7, Block.stoneBrick.blockID);
		world.setBlock(i + 9, j + 5, k + 8, Block.stoneBrick.blockID);
		world.setBlock(i + 9, j + 5, k + 9, Block.stoneBrick.blockID);
		world.setBlock(i + 9, j + 5, k + 10, Block.stoneBrick.blockID);
		world.setBlock(i + 9, j + 5, k + 11, Block.stoneBrick.blockID);
		world.setBlock(i + 9, j + 5, k + 12, Block.stoneBrick.blockID);
		world.setBlock(i + 9, j + 5, k + 13, Block.stoneBrick.blockID);
		world.setBlock(i + 9, j + 5, k + 14, Block.stoneBrick.blockID);
		world.setBlock(i + 9, j + 5, k + 15, Block.stoneBrick.blockID);
		world.setBlock(i + 9, j + 5, k + 16, Block.stoneBrick.blockID);
		world.setBlock(i + 9, j + 5, k + 17, Block.stoneBrick.blockID);
		world.setBlock(i + 9, j + 5, k + 18, Block.stoneBrick.blockID);
		world.setBlock(i + 9, j + 5, k + 19, Block.stoneBrick.blockID);
		world.setBlock(i + 9, j + 5, k + 20, Block.stoneBrick.blockID);
		world.setBlock(i + 9, j + 5, k + 21, Block.stoneBrick.blockID);
		world.setBlock(i + 9, j + 5, k + 22, Block.stoneBrick.blockID);
		world.setBlock(i + 9, j + 5, k + 23, Block.stoneBrick.blockID);
		world.setBlock(i + 9, j + 5, k + 24, Block.stoneBrick.blockID);
		world.setBlock(i + 9, j + 5, k + 25, Block.stoneBrick.blockID);
		world.setBlock(i + 9, j + 5, k + 26, Block.stoneBrick.blockID);
		world.setBlock(i + 9, j + 5, k + 27, Block.stoneBrick.blockID);
		world.setBlock(i + 9, j + 5, k + 28, Block.stoneBrick.blockID);
		world.setBlock(i + 9, j + 5, k + 29, Block.stoneBrick.blockID);
		world.setBlock(i + 9, j + 5, k + 30, Block.stoneBrick.blockID);
		world.setBlock(i + 9, j + 5, k + 31, Block.stoneBrick.blockID);
		world.setBlock(i + 9, j + 5, k + 32, Block.stoneBrick.blockID);
		world.setBlock(i + 9, j + 5, k + 33, Block.stoneBrick.blockID);
		world.setBlock(i + 9, j + 5, k + 34, Block.stoneBrick.blockID);
		world.setBlock(i + 9, j + 5, k + 35, Block.stoneBrick.blockID);
		world.setBlock(i + 9, j + 5, k + 36, Block.stoneBrick.blockID);
		world.setBlock(i + 9, j + 5, k + 37, Block.stoneBrick.blockID);
		world.setBlock(i + 9, j + 5, k + 38, Block.stoneBrick.blockID);
		world.setBlock(i + 9, j + 5, k + 39, Block.stoneBrick.blockID);
		world.setBlock(i + 9, j + 5, k + 40, Block.stoneBrick.blockID);
		world.setBlock(i + 9, j + 5, k + 41, Block.stoneBrick.blockID);
		world.setBlock(i + 9, j + 5, k + 42, Block.stoneBrick.blockID);
		world.setBlock(i + 9, j + 5, k + 43, Block.stoneBrick.blockID);
		world.setBlock(i + 9, j + 5, k + 44, Block.stoneBrick.blockID);
		world.setBlock(i + 9, j + 5, k + 45, Block.stoneBrick.blockID);
		world.setBlock(i + 9, j + 5, k + 46, Block.stoneBrick.blockID);
		world.setBlock(i + 9, j + 5, k + 47, Block.stoneBrick.blockID);
		world.setBlock(i + 9, j + 5, k + 48, Block.stoneBrick.blockID);
		world.setBlock(i + 9, j + 5, k + 49, Block.stoneBrick.blockID);
		world.setBlock(i + 9, j + 5, k + 50, Block.glowStone.blockID);
		world.setBlock(i + 9, j + 5, k + 51, Block.stoneBrick.blockID);
		world.setBlock(i + 9, j + 6, k + 1, Block.stoneBrick.blockID);
		world.setBlock(i + 9, j + 6, k + 51, Block.stoneBrick.blockID);
		world.setBlock(i + 10, j + 0, k + 1, Block.stoneBrick.blockID);
		world.setBlock(i + 10, j + 0, k + 25, Block.stoneBrick.blockID);
		world.setBlock(i + 10, j + 0, k + 51, Block.stoneBrick.blockID);
		world.setBlock(i + 10, j + 1, k + 1, Block.stoneBrick.blockID);
		world.setBlock(i + 10, j + 1, k + 25, Block.stoneBrick.blockID);
		world.setBlock(i + 10, j + 1, k + 51, Block.stoneBrick.blockID);
		world.setBlock(i + 10, j + 2, k + 1, Block.stoneBrick.blockID);
		world.setBlock(i + 10, j + 2, k + 25, Block.stoneBrick.blockID);
		world.setBlock(i + 10, j + 2, k + 51, Block.stoneBrick.blockID);
		world.setBlock(i + 10, j + 3, k + 1, Block.stoneBrick.blockID);
		world.setBlock(i + 10, j + 3, k + 25, Block.stoneBrick.blockID);
		world.setBlock(i + 10, j + 3, k + 51, Block.stoneBrick.blockID);
		world.setBlock(i + 10, j + 4, k + 1, Block.stoneBrick.blockID);
		world.setBlock(i + 10, j + 4, k + 2, Block.glowStone.blockID);
		world.setBlock(i + 10, j + 4, k + 24, Block.glowStone.blockID);
		world.setBlock(i + 10, j + 4, k + 25, Block.stoneBrick.blockID);
		world.setBlock(i + 10, j + 4, k + 50, Block.glowStone.blockID);
		world.setBlock(i + 10, j + 4, k + 51, Block.stoneBrick.blockID);
		world.setBlock(i + 10, j + 5, k + 1, Block.stoneBrick.blockID);
		world.setBlock(i + 10, j + 5, k + 2, Block.glowStone.blockID);
		world.setBlock(i + 10, j + 5, k + 3, Block.stoneBrick.blockID);
		world.setBlock(i + 10, j + 5, k + 4, Block.stoneBrick.blockID);
		world.setBlock(i + 10, j + 5, k + 5, Block.stoneBrick.blockID);
		world.setBlock(i + 10, j + 5, k + 6, Block.stoneBrick.blockID);
		world.setBlock(i + 10, j + 5, k + 7, Block.stoneBrick.blockID);
		world.setBlock(i + 10, j + 5, k + 8, Block.stoneBrick.blockID);
		world.setBlock(i + 10, j + 5, k + 9, Block.stoneBrick.blockID);
		world.setBlock(i + 10, j + 5, k + 10, Block.stoneBrick.blockID);
		world.setBlock(i + 10, j + 5, k + 11, Block.stoneBrick.blockID);
		world.setBlock(i + 10, j + 5, k + 12, Block.stoneBrick.blockID);
		world.setBlock(i + 10, j + 5, k + 13, Block.stoneBrick.blockID);
		world.setBlock(i + 10, j + 5, k + 14, Block.stoneBrick.blockID);
		world.setBlock(i + 10, j + 5, k + 15, Block.stoneBrick.blockID);
		world.setBlock(i + 10, j + 5, k + 16, Block.stoneBrick.blockID);
		world.setBlock(i + 10, j + 5, k + 17, Block.stoneBrick.blockID);
		world.setBlock(i + 10, j + 5, k + 18, Block.stoneBrick.blockID);
		world.setBlock(i + 10, j + 5, k + 19, Block.stoneBrick.blockID);
		world.setBlock(i + 10, j + 5, k + 20, Block.stoneBrick.blockID);
		world.setBlock(i + 10, j + 5, k + 21, Block.stoneBrick.blockID);
		world.setBlock(i + 10, j + 5, k + 22, Block.stoneBrick.blockID);
		world.setBlock(i + 10, j + 5, k + 23, Block.stoneBrick.blockID);
		world.setBlock(i + 10, j + 5, k + 24, Block.stoneBrick.blockID);
		world.setBlock(i + 10, j + 5, k + 25, Block.stoneBrick.blockID);
		world.setBlock(i + 10, j + 5, k + 26, Block.stoneBrick.blockID);
		world.setBlock(i + 10, j + 5, k + 27, Block.stoneBrick.blockID);
		world.setBlock(i + 10, j + 5, k + 28, Block.stoneBrick.blockID);
		world.setBlock(i + 10, j + 5, k + 29, Block.stoneBrick.blockID);
		world.setBlock(i + 10, j + 5, k + 30, Block.stoneBrick.blockID);
		world.setBlock(i + 10, j + 5, k + 31, Block.stoneBrick.blockID);
		world.setBlock(i + 10, j + 5, k + 32, Block.stoneBrick.blockID);
		world.setBlock(i + 10, j + 5, k + 33, Block.stoneBrick.blockID);
		world.setBlock(i + 10, j + 5, k + 34, Block.stoneBrick.blockID);
		world.setBlock(i + 10, j + 5, k + 35, Block.stoneBrick.blockID);
		world.setBlock(i + 10, j + 5, k + 36, Block.stoneBrick.blockID);
		world.setBlock(i + 10, j + 5, k + 37, Block.stoneBrick.blockID);
		world.setBlock(i + 10, j + 5, k + 38, Block.stoneBrick.blockID);
		world.setBlock(i + 10, j + 5, k + 39, Block.stoneBrick.blockID);
		world.setBlock(i + 10, j + 5, k + 40, Block.stoneBrick.blockID);
		world.setBlock(i + 10, j + 5, k + 41, Block.stoneBrick.blockID);
		world.setBlock(i + 10, j + 5, k + 42, Block.stoneBrick.blockID);
		world.setBlock(i + 10, j + 5, k + 43, Block.stoneBrick.blockID);
		world.setBlock(i + 10, j + 5, k + 44, Block.stoneBrick.blockID);
		world.setBlock(i + 10, j + 5, k + 45, Block.stoneBrick.blockID);
		world.setBlock(i + 10, j + 5, k + 46, Block.stoneBrick.blockID);
		world.setBlock(i + 10, j + 5, k + 47, Block.stoneBrick.blockID);
		world.setBlock(i + 10, j + 5, k + 48, Block.stoneBrick.blockID);
		world.setBlock(i + 10, j + 5, k + 49, Block.stoneBrick.blockID);
		world.setBlock(i + 10, j + 5, k + 50, Block.glowStone.blockID);
		world.setBlock(i + 10, j + 5, k + 51, Block.stoneBrick.blockID);
		world.setBlock(i + 10, j + 6, k + 1, Block.stoneBrick.blockID);
		world.setBlock(i + 10, j + 6, k + 51, Block.stoneBrick.blockID);
		world.setBlock(i + 10, j + 7, k + 1, Block.stoneBrick.blockID);
		world.setBlock(i + 10, j + 7, k + 51, Block.stoneBrick.blockID);
		world.setBlock(i + 11, j + 0, k + 1, Block.stoneBrick.blockID);
		world.setBlock(i + 11, j + 0, k + 25, Block.stoneBrick.blockID);
		world.setBlock(i + 11, j + 0, k + 51, Block.stoneBrick.blockID);
		world.setBlock(i + 11, j + 1, k + 1, Block.stoneBrick.blockID);
		world.setBlock(i + 11, j + 1, k + 25, Block.stoneBrick.blockID);
		world.setBlock(i + 11, j + 1, k + 51, Block.stoneBrick.blockID);
		world.setBlock(i + 11, j + 2, k + 1, Block.stoneBrick.blockID);
		world.setBlock(i + 11, j + 2, k + 25, Block.stoneBrick.blockID);
		world.setBlock(i + 11, j + 2, k + 51, Block.stoneBrick.blockID);
		world.setBlock(i + 11, j + 3, k + 1, Block.stoneBrick.blockID);
		world.setBlock(i + 11, j + 3, k + 25, Block.stoneBrick.blockID);
		world.setBlock(i + 11, j + 3, k + 51, Block.stoneBrick.blockID);
		world.setBlock(i + 11, j + 4, k + 1, Block.stoneBrick.blockID);
		world.setBlock(i + 11, j + 4, k + 2, Block.glowStone.blockID);
		world.setBlock(i + 11, j + 4, k + 24, Block.glowStone.blockID);
		world.setBlock(i + 11, j + 4, k + 25, Block.stoneBrick.blockID);
		world.setBlock(i + 11, j + 4, k + 50, Block.glowStone.blockID);
		world.setBlock(i + 11, j + 4, k + 51, Block.stoneBrick.blockID);
		world.setBlock(i + 11, j + 5, k + 1, Block.stoneBrick.blockID);
		world.setBlock(i + 11, j + 5, k + 2, Block.glowStone.blockID);
		world.setBlock(i + 11, j + 5, k + 3, Block.stoneBrick.blockID);
		world.setBlock(i + 11, j + 5, k + 4, Block.stoneBrick.blockID);
		world.setBlock(i + 11, j + 5, k + 5, Block.stoneBrick.blockID);
		world.setBlock(i + 11, j + 5, k + 6, Block.stoneBrick.blockID);
		world.setBlock(i + 11, j + 5, k + 7, Block.stoneBrick.blockID);
		world.setBlock(i + 11, j + 5, k + 8, Block.stoneBrick.blockID);
		world.setBlock(i + 11, j + 5, k + 9, Block.stoneBrick.blockID);
		world.setBlock(i + 11, j + 5, k + 10, Block.stoneBrick.blockID);
		world.setBlock(i + 11, j + 5, k + 11, Block.stoneBrick.blockID);
		world.setBlock(i + 11, j + 5, k + 12, Block.stoneBrick.blockID);
		world.setBlock(i + 11, j + 5, k + 13, Block.stoneBrick.blockID);
		world.setBlock(i + 11, j + 5, k + 14, Block.stoneBrick.blockID);
		world.setBlock(i + 11, j + 5, k + 15, Block.stoneBrick.blockID);
		world.setBlock(i + 11, j + 5, k + 16, Block.stoneBrick.blockID);
		world.setBlock(i + 11, j + 5, k + 17, Block.stoneBrick.blockID);
		world.setBlock(i + 11, j + 5, k + 18, Block.stoneBrick.blockID);
		world.setBlock(i + 11, j + 5, k + 19, Block.stoneBrick.blockID);
		world.setBlock(i + 11, j + 5, k + 20, Block.stoneBrick.blockID);
		world.setBlock(i + 11, j + 5, k + 21, Block.stoneBrick.blockID);
		world.setBlock(i + 11, j + 5, k + 22, Block.stoneBrick.blockID);
		world.setBlock(i + 11, j + 5, k + 23, Block.stoneBrick.blockID);
		world.setBlock(i + 11, j + 5, k + 24, Block.stoneBrick.blockID);
		world.setBlock(i + 11, j + 5, k + 25, Block.stoneBrick.blockID);
		world.setBlock(i + 11, j + 5, k + 26, Block.stoneBrick.blockID);
		world.setBlock(i + 11, j + 5, k + 27, Block.stoneBrick.blockID);
		world.setBlock(i + 11, j + 5, k + 28, Block.stoneBrick.blockID);
		world.setBlock(i + 11, j + 5, k + 29, Block.stoneBrick.blockID);
		world.setBlock(i + 11, j + 5, k + 30, Block.stoneBrick.blockID);
		world.setBlock(i + 11, j + 5, k + 31, Block.stoneBrick.blockID);
		world.setBlock(i + 11, j + 5, k + 32, Block.stoneBrick.blockID);
		world.setBlock(i + 11, j + 5, k + 33, Block.stoneBrick.blockID);
		world.setBlock(i + 11, j + 5, k + 34, Block.stoneBrick.blockID);
		world.setBlock(i + 11, j + 5, k + 35, Block.stoneBrick.blockID);
		world.setBlock(i + 11, j + 5, k + 36, Block.stoneBrick.blockID);
		world.setBlock(i + 11, j + 5, k + 37, Block.stoneBrick.blockID);
		world.setBlock(i + 11, j + 5, k + 38, Block.stoneBrick.blockID);
		world.setBlock(i + 11, j + 5, k + 39, Block.stoneBrick.blockID);
		world.setBlock(i + 11, j + 5, k + 40, Block.stoneBrick.blockID);
		world.setBlock(i + 11, j + 5, k + 41, Block.stoneBrick.blockID);
		world.setBlock(i + 11, j + 5, k + 42, Block.stoneBrick.blockID);
		world.setBlock(i + 11, j + 5, k + 43, Block.stoneBrick.blockID);
		world.setBlock(i + 11, j + 5, k + 44, Block.stoneBrick.blockID);
		world.setBlock(i + 11, j + 5, k + 45, Block.stoneBrick.blockID);
		world.setBlock(i + 11, j + 5, k + 46, Block.stoneBrick.blockID);
		world.setBlock(i + 11, j + 5, k + 47, Block.stoneBrick.blockID);
		world.setBlock(i + 11, j + 5, k + 48, Block.stoneBrick.blockID);
		world.setBlock(i + 11, j + 5, k + 49, Block.stoneBrick.blockID);
		world.setBlock(i + 11, j + 5, k + 50, Block.glowStone.blockID);
		world.setBlock(i + 11, j + 5, k + 51, Block.stoneBrick.blockID);
		world.setBlock(i + 11, j + 6, k + 1, Block.stoneBrick.blockID);
		world.setBlock(i + 11, j + 6, k + 51, Block.stoneBrick.blockID);
		world.setBlock(i + 12, j + 0, k + 1, Block.stoneBrick.blockID);
		world.setBlock(i + 12, j + 0, k + 25, Block.stoneBrick.blockID);
		world.setBlock(i + 12, j + 0, k + 51, Block.stoneBrick.blockID);
		world.setBlock(i + 12, j + 1, k + 1, Block.stoneBrick.blockID);
		world.setBlock(i + 12, j + 1, k + 25, Block.stoneBrick.blockID);
		world.setBlock(i + 12, j + 1, k + 51, Block.stoneBrick.blockID);
		world.setBlock(i + 12, j + 2, k + 1, Block.stoneBrick.blockID);
		world.setBlock(i + 12, j + 2, k + 25, Block.stoneBrick.blockID);
		world.setBlock(i + 12, j + 2, k + 51, Block.stoneBrick.blockID);
		world.setBlock(i + 12, j + 3, k + 1, Block.stoneBrick.blockID);
		world.setBlock(i + 12, j + 3, k + 25, Block.stoneBrick.blockID);
		world.setBlock(i + 12, j + 3, k + 51, Block.stoneBrick.blockID);
		world.setBlock(i + 12, j + 4, k + 1, Block.stoneBrick.blockID);
		world.setBlock(i + 12, j + 4, k + 2, Block.glowStone.blockID);
		world.setBlock(i + 12, j + 4, k + 24, Block.glowStone.blockID);
		world.setBlock(i + 12, j + 4, k + 25, Block.stoneBrick.blockID);
		world.setBlock(i + 12, j + 4, k + 50, Block.glowStone.blockID);
		world.setBlock(i + 12, j + 4, k + 51, Block.stoneBrick.blockID);
		world.setBlock(i + 12, j + 5, k + 1, Block.stoneBrick.blockID);
		world.setBlock(i + 12, j + 5, k + 2, Block.glowStone.blockID);
		world.setBlock(i + 12, j + 5, k + 3, Block.stoneBrick.blockID);
		world.setBlock(i + 12, j + 5, k + 4, Block.stoneBrick.blockID);
		world.setBlock(i + 12, j + 5, k + 5, Block.stoneBrick.blockID);
		world.setBlock(i + 12, j + 5, k + 6, Block.stoneBrick.blockID);
		world.setBlock(i + 12, j + 5, k + 7, Block.stoneBrick.blockID);
		world.setBlock(i + 12, j + 5, k + 8, Block.stoneBrick.blockID);
		world.setBlock(i + 12, j + 5, k + 9, Block.stoneBrick.blockID);
		world.setBlock(i + 12, j + 5, k + 10, Block.stoneBrick.blockID);
		world.setBlock(i + 12, j + 5, k + 11, Block.stoneBrick.blockID);
		world.setBlock(i + 12, j + 5, k + 12, Block.stoneBrick.blockID);
		world.setBlock(i + 12, j + 5, k + 13, Block.stoneBrick.blockID);
		world.setBlock(i + 12, j + 5, k + 14, Block.stoneBrick.blockID);
		world.setBlock(i + 12, j + 5, k + 15, Block.stoneBrick.blockID);
		world.setBlock(i + 12, j + 5, k + 16, Block.stoneBrick.blockID);
		world.setBlock(i + 12, j + 5, k + 17, Block.stoneBrick.blockID);
		world.setBlock(i + 12, j + 5, k + 18, Block.stoneBrick.blockID);
		world.setBlock(i + 12, j + 5, k + 19, Block.stoneBrick.blockID);
		world.setBlock(i + 12, j + 5, k + 20, Block.stoneBrick.blockID);
		world.setBlock(i + 12, j + 5, k + 21, Block.stoneBrick.blockID);
		world.setBlock(i + 12, j + 5, k + 22, Block.stoneBrick.blockID);
		world.setBlock(i + 12, j + 5, k + 23, Block.stoneBrick.blockID);
		world.setBlock(i + 12, j + 5, k + 24, Block.stoneBrick.blockID);
		world.setBlock(i + 12, j + 5, k + 25, Block.stoneBrick.blockID);
		world.setBlock(i + 12, j + 5, k + 26, Block.stoneBrick.blockID);
		world.setBlock(i + 12, j + 5, k + 27, Block.stoneBrick.blockID);
		world.setBlock(i + 12, j + 5, k + 28, Block.stoneBrick.blockID);
		world.setBlock(i + 12, j + 5, k + 29, Block.stoneBrick.blockID);
		world.setBlock(i + 12, j + 5, k + 30, Block.stoneBrick.blockID);
		world.setBlock(i + 12, j + 5, k + 31, Block.stoneBrick.blockID);
		world.setBlock(i + 12, j + 5, k + 32, Block.stoneBrick.blockID);
		world.setBlock(i + 12, j + 5, k + 33, Block.stoneBrick.blockID);
		world.setBlock(i + 12, j + 5, k + 34, Block.stoneBrick.blockID);
		world.setBlock(i + 12, j + 5, k + 35, Block.stoneBrick.blockID);
		world.setBlock(i + 12, j + 5, k + 36, Block.stoneBrick.blockID);
		world.setBlock(i + 12, j + 5, k + 37, Block.stoneBrick.blockID);
		world.setBlock(i + 12, j + 5, k + 38, Block.stoneBrick.blockID);
		world.setBlock(i + 12, j + 5, k + 39, Block.stoneBrick.blockID);
		world.setBlock(i + 12, j + 5, k + 40, Block.stoneBrick.blockID);
		world.setBlock(i + 12, j + 5, k + 41, Block.stoneBrick.blockID);
		world.setBlock(i + 12, j + 5, k + 42, Block.stoneBrick.blockID);
		world.setBlock(i + 12, j + 5, k + 43, Block.stoneBrick.blockID);
		world.setBlock(i + 12, j + 5, k + 44, Block.stoneBrick.blockID);
		world.setBlock(i + 12, j + 5, k + 45, Block.stoneBrick.blockID);
		world.setBlock(i + 12, j + 5, k + 46, Block.stoneBrick.blockID);
		world.setBlock(i + 12, j + 5, k + 47, Block.stoneBrick.blockID);
		world.setBlock(i + 12, j + 5, k + 48, Block.stoneBrick.blockID);
		world.setBlock(i + 12, j + 5, k + 49, Block.stoneBrick.blockID);
		world.setBlock(i + 12, j + 5, k + 50, Block.glowStone.blockID);
		world.setBlock(i + 12, j + 5, k + 51, Block.stoneBrick.blockID);
		world.setBlock(i + 12, j + 6, k + 1, Block.stoneBrick.blockID);
		world.setBlock(i + 12, j + 6, k + 51, Block.stoneBrick.blockID);
		world.setBlock(i + 12, j + 7, k + 1, Block.stoneBrick.blockID);
		world.setBlock(i + 12, j + 7, k + 51, Block.stoneBrick.blockID);
		world.setBlock(i + 13, j + 0, k + 1, Block.stoneBrick.blockID);
		world.setBlock(i + 13, j + 0, k + 25, Block.stoneBrick.blockID);
		world.setBlock(i + 13, j + 0, k + 51, Block.stoneBrick.blockID);
		world.setBlock(i + 13, j + 1, k + 1, Block.stoneBrick.blockID);
		world.setBlock(i + 13, j + 1, k + 25, Block.stoneBrick.blockID);
		world.setBlock(i + 13, j + 1, k + 51, Block.stoneBrick.blockID);
		world.setBlock(i + 13, j + 2, k + 1, Block.stoneBrick.blockID);
		world.setBlock(i + 13, j + 2, k + 25, Block.stoneBrick.blockID);
		world.setBlock(i + 13, j + 2, k + 51, Block.stoneBrick.blockID);
		world.setBlock(i + 13, j + 3, k + 1, Block.stoneBrick.blockID);
		world.setBlock(i + 13, j + 3, k + 25, Block.stoneBrick.blockID);
		world.setBlock(i + 13, j + 3, k + 51, Block.stoneBrick.blockID);
		world.setBlock(i + 13, j + 4, k + 1, Block.stoneBrick.blockID);
		world.setBlock(i + 13, j + 4, k + 2, Block.glowStone.blockID);
		world.setBlock(i + 13, j + 4, k + 24, Block.glowStone.blockID);
		world.setBlock(i + 13, j + 4, k + 25, Block.stoneBrick.blockID);
		world.setBlock(i + 13, j + 4, k + 50, Block.glowStone.blockID);
		world.setBlock(i + 13, j + 4, k + 51, Block.stoneBrick.blockID);
		world.setBlock(i + 13, j + 5, k + 1, Block.stoneBrick.blockID);
		world.setBlock(i + 13, j + 5, k + 2, Block.glowStone.blockID);
		world.setBlock(i + 13, j + 5, k + 3, Block.stoneBrick.blockID);
		world.setBlock(i + 13, j + 5, k + 4, Block.stoneBrick.blockID);
		world.setBlock(i + 13, j + 5, k + 5, Block.stoneBrick.blockID);
		world.setBlock(i + 13, j + 5, k + 6, Block.stoneBrick.blockID);
		world.setBlock(i + 13, j + 5, k + 7, Block.stoneBrick.blockID);
		world.setBlock(i + 13, j + 5, k + 8, Block.stoneBrick.blockID);
		world.setBlock(i + 13, j + 5, k + 9, Block.stoneBrick.blockID);
		world.setBlock(i + 13, j + 5, k + 10, Block.stoneBrick.blockID);
		world.setBlock(i + 13, j + 5, k + 11, Block.stoneBrick.blockID);
		world.setBlock(i + 13, j + 5, k + 12, Block.stoneBrick.blockID);
		world.setBlock(i + 13, j + 5, k + 13, Block.stoneBrick.blockID);
		world.setBlock(i + 13, j + 5, k + 14, Block.stoneBrick.blockID);
		world.setBlock(i + 13, j + 5, k + 15, Block.stoneBrick.blockID);
		world.setBlock(i + 13, j + 5, k + 16, Block.stoneBrick.blockID);
		world.setBlock(i + 13, j + 5, k + 17, Block.stoneBrick.blockID);
		world.setBlock(i + 13, j + 5, k + 18, Block.stoneBrick.blockID);
		world.setBlock(i + 13, j + 5, k + 19, Block.stoneBrick.blockID);
		world.setBlock(i + 13, j + 5, k + 20, Block.stoneBrick.blockID);
		world.setBlock(i + 13, j + 5, k + 21, Block.stoneBrick.blockID);
		world.setBlock(i + 13, j + 5, k + 22, Block.stoneBrick.blockID);
		world.setBlock(i + 13, j + 5, k + 23, Block.stoneBrick.blockID);
		world.setBlock(i + 13, j + 5, k + 24, Block.stoneBrick.blockID);
		world.setBlock(i + 13, j + 5, k + 25, Block.stoneBrick.blockID);
		world.setBlock(i + 13, j + 5, k + 26, Block.stoneBrick.blockID);
		world.setBlock(i + 13, j + 5, k + 27, Block.stoneBrick.blockID);
		world.setBlock(i + 13, j + 5, k + 28, Block.stoneBrick.blockID);
		world.setBlock(i + 13, j + 5, k + 29, Block.stoneBrick.blockID);
		world.setBlock(i + 13, j + 5, k + 30, Block.stoneBrick.blockID);
		world.setBlock(i + 13, j + 5, k + 31, Block.stoneBrick.blockID);
		world.setBlock(i + 13, j + 5, k + 32, Block.stoneBrick.blockID);
		world.setBlock(i + 13, j + 5, k + 33, Block.stoneBrick.blockID);
		world.setBlock(i + 13, j + 5, k + 34, Block.stoneBrick.blockID);
		world.setBlock(i + 13, j + 5, k + 35, Block.stoneBrick.blockID);
		world.setBlock(i + 13, j + 5, k + 36, Block.stoneBrick.blockID);
		world.setBlock(i + 13, j + 5, k + 37, Block.stoneBrick.blockID);
		world.setBlock(i + 13, j + 5, k + 38, Block.stoneBrick.blockID);
		world.setBlock(i + 13, j + 5, k + 39, Block.stoneBrick.blockID);
		world.setBlock(i + 13, j + 5, k + 40, Block.stoneBrick.blockID);
		world.setBlock(i + 13, j + 5, k + 41, Block.stoneBrick.blockID);
		world.setBlock(i + 13, j + 5, k + 42, Block.stoneBrick.blockID);
		world.setBlock(i + 13, j + 5, k + 43, Block.stoneBrick.blockID);
		world.setBlock(i + 13, j + 5, k + 44, Block.stoneBrick.blockID);
		world.setBlock(i + 13, j + 5, k + 45, Block.stoneBrick.blockID);
		world.setBlock(i + 13, j + 5, k + 46, Block.stoneBrick.blockID);
		world.setBlock(i + 13, j + 5, k + 47, Block.stoneBrick.blockID);
		world.setBlock(i + 13, j + 5, k + 48, Block.stoneBrick.blockID);
		world.setBlock(i + 13, j + 5, k + 49, Block.stoneBrick.blockID);
		world.setBlock(i + 13, j + 5, k + 50, Block.glowStone.blockID);
		world.setBlock(i + 13, j + 5, k + 51, Block.stoneBrick.blockID);
		world.setBlock(i + 13, j + 6, k + 1, Block.stoneBrick.blockID);
		world.setBlock(i + 13, j + 6, k + 51, Block.stoneBrick.blockID);
		world.setBlock(i + 14, j + 0, k + 1, Block.stoneBrick.blockID);
		world.setBlock(i + 14, j + 0, k + 25, Block.stoneBrick.blockID);
		world.setBlock(i + 14, j + 0, k + 51, Block.stoneBrick.blockID);
		world.setBlock(i + 14, j + 1, k + 1, Block.stoneBrick.blockID);
		world.setBlock(i + 14, j + 1, k + 25, Block.stoneBrick.blockID);
		world.setBlock(i + 14, j + 1, k + 51, Block.stoneBrick.blockID);
		world.setBlock(i + 14, j + 2, k + 1, Block.stoneBrick.blockID);
		world.setBlock(i + 14, j + 2, k + 25, Block.stoneBrick.blockID);
		world.setBlock(i + 14, j + 2, k + 51, Block.stoneBrick.blockID);
		world.setBlock(i + 14, j + 3, k + 1, Block.stoneBrick.blockID);
		world.setBlock(i + 14, j + 3, k + 25, Block.stoneBrick.blockID);
		world.setBlock(i + 14, j + 3, k + 51, Block.stoneBrick.blockID);
		world.setBlock(i + 14, j + 4, k + 1, Block.stoneBrick.blockID);
		world.setBlock(i + 14, j + 4, k + 2, Block.glowStone.blockID);
		world.setBlock(i + 14, j + 4, k + 24, Block.glowStone.blockID);
		world.setBlock(i + 14, j + 4, k + 25, Block.stoneBrick.blockID);
		world.setBlock(i + 14, j + 4, k + 50, Block.glowStone.blockID);
		world.setBlock(i + 14, j + 4, k + 51, Block.stoneBrick.blockID);
		world.setBlock(i + 14, j + 5, k + 1, Block.stoneBrick.blockID);
		world.setBlock(i + 14, j + 5, k + 2, Block.glowStone.blockID);
		world.setBlock(i + 14, j + 5, k + 3, Block.stoneBrick.blockID);
		world.setBlock(i + 14, j + 5, k + 4, Block.stoneBrick.blockID);
		world.setBlock(i + 14, j + 5, k + 5, Block.stoneBrick.blockID);
		world.setBlock(i + 14, j + 5, k + 6, Block.stoneBrick.blockID);
		world.setBlock(i + 14, j + 5, k + 7, Block.stoneBrick.blockID);
		world.setBlock(i + 14, j + 5, k + 8, Block.stoneBrick.blockID);
		world.setBlock(i + 14, j + 5, k + 9, Block.stoneBrick.blockID);
		world.setBlock(i + 14, j + 5, k + 10, Block.stoneBrick.blockID);
		world.setBlock(i + 14, j + 5, k + 11, Block.stoneBrick.blockID);
		world.setBlock(i + 14, j + 5, k + 12, Block.stoneBrick.blockID);
		world.setBlock(i + 14, j + 5, k + 13, Block.stoneBrick.blockID);
		world.setBlock(i + 14, j + 5, k + 14, Block.stoneBrick.blockID);
		world.setBlock(i + 14, j + 5, k + 15, Block.stoneBrick.blockID);
		world.setBlock(i + 14, j + 5, k + 16, Block.stoneBrick.blockID);
		world.setBlock(i + 14, j + 5, k + 17, Block.stoneBrick.blockID);
		world.setBlock(i + 14, j + 5, k + 18, Block.stoneBrick.blockID);
		world.setBlock(i + 14, j + 5, k + 19, Block.stoneBrick.blockID);
		world.setBlock(i + 14, j + 5, k + 20, Block.stoneBrick.blockID);
		world.setBlock(i + 14, j + 5, k + 21, Block.stoneBrick.blockID);
		world.setBlock(i + 14, j + 5, k + 22, Block.stoneBrick.blockID);
		world.setBlock(i + 14, j + 5, k + 23, Block.stoneBrick.blockID);
		world.setBlock(i + 14, j + 5, k + 24, Block.stoneBrick.blockID);
		world.setBlock(i + 14, j + 5, k + 25, Block.stoneBrick.blockID);
		world.setBlock(i + 14, j + 5, k + 26, Block.stoneBrick.blockID);
		world.setBlock(i + 14, j + 5, k + 27, Block.stoneBrick.blockID);
		world.setBlock(i + 14, j + 5, k + 28, Block.stoneBrick.blockID);
		world.setBlock(i + 14, j + 5, k + 29, Block.stoneBrick.blockID);
		world.setBlock(i + 14, j + 5, k + 30, Block.stoneBrick.blockID);
		world.setBlock(i + 14, j + 5, k + 31, Block.stoneBrick.blockID);
		world.setBlock(i + 14, j + 5, k + 32, Block.stoneBrick.blockID);
		world.setBlock(i + 14, j + 5, k + 33, Block.stoneBrick.blockID);
		world.setBlock(i + 14, j + 5, k + 34, Block.stoneBrick.blockID);
		world.setBlock(i + 14, j + 5, k + 35, Block.stoneBrick.blockID);
		world.setBlock(i + 14, j + 5, k + 36, Block.stoneBrick.blockID);
		world.setBlock(i + 14, j + 5, k + 37, Block.stoneBrick.blockID);
		world.setBlock(i + 14, j + 5, k + 38, Block.stoneBrick.blockID);
		world.setBlock(i + 14, j + 5, k + 39, Block.stoneBrick.blockID);
		world.setBlock(i + 14, j + 5, k + 40, Block.stoneBrick.blockID);
		world.setBlock(i + 14, j + 5, k + 41, Block.stoneBrick.blockID);
		world.setBlock(i + 14, j + 5, k + 42, Block.stoneBrick.blockID);
		world.setBlock(i + 14, j + 5, k + 43, Block.stoneBrick.blockID);
		world.setBlock(i + 14, j + 5, k + 44, Block.stoneBrick.blockID);
		world.setBlock(i + 14, j + 5, k + 45, Block.stoneBrick.blockID);
		world.setBlock(i + 14, j + 5, k + 46, Block.stoneBrick.blockID);
		world.setBlock(i + 14, j + 5, k + 47, Block.stoneBrick.blockID);
		world.setBlock(i + 14, j + 5, k + 48, Block.stoneBrick.blockID);
		world.setBlock(i + 14, j + 5, k + 49, Block.stoneBrick.blockID);
		world.setBlock(i + 14, j + 5, k + 50, Block.glowStone.blockID);
		world.setBlock(i + 14, j + 5, k + 51, Block.stoneBrick.blockID);
		world.setBlock(i + 14, j + 6, k + 1, Block.stoneBrick.blockID);
		world.setBlock(i + 14, j + 6, k + 51, Block.stoneBrick.blockID);
		world.setBlock(i + 14, j + 7, k + 1, Block.stoneBrick.blockID);
		world.setBlock(i + 14, j + 7, k + 51, Block.stoneBrick.blockID);
		world.setBlock(i + 15, j + 0, k + 1, Block.stoneBrick.blockID);
		world.setBlock(i + 15, j + 0, k + 25, Block.stoneBrick.blockID);
		world.setBlock(i + 15, j + 0, k + 51, Block.stoneBrick.blockID);
		world.setBlock(i + 15, j + 1, k + 1, Block.stoneBrick.blockID);
		world.setBlock(i + 15, j + 1, k + 25, Block.stoneBrick.blockID);
		world.setBlock(i + 15, j + 1, k + 51, Block.stoneBrick.blockID);
		world.setBlock(i + 15, j + 2, k + 1, Block.stoneBrick.blockID);
		world.setBlock(i + 15, j + 2, k + 25, Block.stoneBrick.blockID);
		world.setBlock(i + 15, j + 2, k + 51, Block.stoneBrick.blockID);
		world.setBlock(i + 15, j + 3, k + 1, Block.stoneBrick.blockID);
		world.setBlock(i + 15, j + 3, k + 25, Block.stoneBrick.blockID);
		world.setBlock(i + 15, j + 3, k + 51, Block.stoneBrick.blockID);
		world.setBlock(i + 15, j + 4, k + 1, Block.stoneBrick.blockID);
		world.setBlock(i + 15, j + 4, k + 2, Block.glowStone.blockID);
		world.setBlock(i + 15, j + 4, k + 24, Block.glowStone.blockID);
		world.setBlock(i + 15, j + 4, k + 25, Block.stoneBrick.blockID);
		world.setBlock(i + 15, j + 4, k + 50, Block.glowStone.blockID);
		world.setBlock(i + 15, j + 4, k + 51, Block.stoneBrick.blockID);
		world.setBlock(i + 15, j + 5, k + 1, Block.stoneBrick.blockID);
		world.setBlock(i + 15, j + 5, k + 2, Block.glowStone.blockID);
		world.setBlock(i + 15, j + 5, k + 3, Block.stoneBrick.blockID);
		world.setBlock(i + 15, j + 5, k + 4, Block.stoneBrick.blockID);
		world.setBlock(i + 15, j + 5, k + 5, Block.stoneBrick.blockID);
		world.setBlock(i + 15, j + 5, k + 6, Block.stoneBrick.blockID);
		world.setBlock(i + 15, j + 5, k + 7, Block.stoneBrick.blockID);
		world.setBlock(i + 15, j + 5, k + 8, Block.stoneBrick.blockID);
		world.setBlock(i + 15, j + 5, k + 9, Block.stoneBrick.blockID);
		world.setBlock(i + 15, j + 5, k + 10, Block.stoneBrick.blockID);
		world.setBlock(i + 15, j + 5, k + 11, Block.stoneBrick.blockID);
		world.setBlock(i + 15, j + 5, k + 12, Block.stoneBrick.blockID);
		world.setBlock(i + 15, j + 5, k + 13, Block.stoneBrick.blockID);
		world.setBlock(i + 15, j + 5, k + 14, Block.stoneBrick.blockID);
		world.setBlock(i + 15, j + 5, k + 15, Block.stoneBrick.blockID);
		world.setBlock(i + 15, j + 5, k + 16, Block.stoneBrick.blockID);
		world.setBlock(i + 15, j + 5, k + 17, Block.stoneBrick.blockID);
		world.setBlock(i + 15, j + 5, k + 18, Block.stoneBrick.blockID);
		world.setBlock(i + 15, j + 5, k + 19, Block.stoneBrick.blockID);
		world.setBlock(i + 15, j + 5, k + 20, Block.stoneBrick.blockID);
		world.setBlock(i + 15, j + 5, k + 21, Block.stoneBrick.blockID);
		world.setBlock(i + 15, j + 5, k + 22, Block.stoneBrick.blockID);
		world.setBlock(i + 15, j + 5, k + 23, Block.stoneBrick.blockID);
		world.setBlock(i + 15, j + 5, k + 24, Block.stoneBrick.blockID);
		world.setBlock(i + 15, j + 5, k + 25, Block.stoneBrick.blockID);
		world.setBlock(i + 15, j + 5, k + 26, Block.stoneBrick.blockID);
		world.setBlock(i + 15, j + 5, k + 27, Block.stoneBrick.blockID);
		world.setBlock(i + 15, j + 5, k + 28, Block.stoneBrick.blockID);
		world.setBlock(i + 15, j + 5, k + 29, Block.stoneBrick.blockID);
		world.setBlock(i + 15, j + 5, k + 30, Block.stoneBrick.blockID);
		world.setBlock(i + 15, j + 5, k + 31, Block.stoneBrick.blockID);
		world.setBlock(i + 15, j + 5, k + 32, Block.stoneBrick.blockID);
		world.setBlock(i + 15, j + 5, k + 33, Block.stoneBrick.blockID);
		world.setBlock(i + 15, j + 5, k + 34, Block.stoneBrick.blockID);
		world.setBlock(i + 15, j + 5, k + 35, Block.stoneBrick.blockID);
		world.setBlock(i + 15, j + 5, k + 36, Block.stoneBrick.blockID);
		world.setBlock(i + 15, j + 5, k + 37, Block.stoneBrick.blockID);
		world.setBlock(i + 15, j + 5, k + 38, Block.stoneBrick.blockID);
		world.setBlock(i + 15, j + 5, k + 39, Block.stoneBrick.blockID);
		world.setBlock(i + 15, j + 5, k + 40, Block.stoneBrick.blockID);
		world.setBlock(i + 15, j + 5, k + 41, Block.stoneBrick.blockID);
		world.setBlock(i + 15, j + 5, k + 42, Block.stoneBrick.blockID);
		world.setBlock(i + 15, j + 5, k + 43, Block.stoneBrick.blockID);
		world.setBlock(i + 15, j + 5, k + 44, Block.stoneBrick.blockID);
		world.setBlock(i + 15, j + 5, k + 45, Block.stoneBrick.blockID);
		world.setBlock(i + 15, j + 5, k + 46, Block.stoneBrick.blockID);
		world.setBlock(i + 15, j + 5, k + 47, Block.stoneBrick.blockID);
		world.setBlock(i + 15, j + 5, k + 48, Block.stoneBrick.blockID);
		world.setBlock(i + 15, j + 5, k + 49, Block.stoneBrick.blockID);
		world.setBlock(i + 15, j + 5, k + 50, Block.glowStone.blockID);
		world.setBlock(i + 15, j + 5, k + 51, Block.stoneBrick.blockID);
		world.setBlock(i + 15, j + 6, k + 1, Block.stoneBrick.blockID);
		world.setBlock(i + 15, j + 6, k + 51, Block.stoneBrick.blockID);
		world.setBlock(i + 16, j + 0, k + 1, Block.stoneBrick.blockID);
		world.setBlock(i + 16, j + 0, k + 25, Block.stoneBrick.blockID);
		world.setBlock(i + 16, j + 0, k + 51, Block.stoneBrick.blockID);
		world.setBlock(i + 16, j + 1, k + 1, Block.stoneBrick.blockID);
		world.setBlock(i + 16, j + 1, k + 25, Block.stoneBrick.blockID);
		world.setBlock(i + 16, j + 1, k + 51, Block.stoneBrick.blockID);
		world.setBlock(i + 16, j + 2, k + 1, Block.stoneBrick.blockID);
		world.setBlock(i + 16, j + 2, k + 25, Block.stoneBrick.blockID);
		world.setBlock(i + 16, j + 2, k + 51, Block.stoneBrick.blockID);
		world.setBlock(i + 16, j + 3, k + 1, Block.stoneBrick.blockID);
		world.setBlock(i + 16, j + 3, k + 25, Block.stoneBrick.blockID);
		world.setBlock(i + 16, j + 3, k + 51, Block.stoneBrick.blockID);
		world.setBlock(i + 16, j + 4, k + 1, Block.stoneBrick.blockID);
		world.setBlock(i + 16, j + 4, k + 2, Block.glowStone.blockID);
		world.setBlock(i + 16, j + 4, k + 24, Block.glowStone.blockID);
		world.setBlock(i + 16, j + 4, k + 25, Block.stoneBrick.blockID);
		world.setBlock(i + 16, j + 4, k + 50, Block.glowStone.blockID);
		world.setBlock(i + 16, j + 4, k + 51, Block.stoneBrick.blockID);
		world.setBlock(i + 16, j + 5, k + 1, Block.stoneBrick.blockID);
		world.setBlock(i + 16, j + 5, k + 2, Block.glowStone.blockID);
		world.setBlock(i + 16, j + 5, k + 3, Block.stoneBrick.blockID);
		world.setBlock(i + 16, j + 5, k + 4, Block.stoneBrick.blockID);
		world.setBlock(i + 16, j + 5, k + 5, Block.stoneBrick.blockID);
		world.setBlock(i + 16, j + 5, k + 6, Block.stoneBrick.blockID);
		world.setBlock(i + 16, j + 5, k + 7, Block.stoneBrick.blockID);
		world.setBlock(i + 16, j + 5, k + 8, Block.stoneBrick.blockID);
		world.setBlock(i + 16, j + 5, k + 9, Block.stoneBrick.blockID);
		world.setBlock(i + 16, j + 5, k + 10, Block.stoneBrick.blockID);
		world.setBlock(i + 16, j + 5, k + 11, Block.stoneBrick.blockID);
		world.setBlock(i + 16, j + 5, k + 12, Block.stoneBrick.blockID);
		world.setBlock(i + 16, j + 5, k + 13, Block.stoneBrick.blockID);
		world.setBlock(i + 16, j + 5, k + 14, Block.stoneBrick.blockID);
		world.setBlock(i + 16, j + 5, k + 15, Block.stoneBrick.blockID);
		world.setBlock(i + 16, j + 5, k + 16, Block.stoneBrick.blockID);
		world.setBlock(i + 16, j + 5, k + 17, Block.stoneBrick.blockID);
		world.setBlock(i + 16, j + 5, k + 18, Block.stoneBrick.blockID);
		world.setBlock(i + 16, j + 5, k + 19, Block.stoneBrick.blockID);
		world.setBlock(i + 16, j + 5, k + 20, Block.stoneBrick.blockID);
		world.setBlock(i + 16, j + 5, k + 21, Block.stoneBrick.blockID);
		world.setBlock(i + 16, j + 5, k + 22, Block.stoneBrick.blockID);
		world.setBlock(i + 16, j + 5, k + 23, Block.stoneBrick.blockID);
		world.setBlock(i + 16, j + 5, k + 24, Block.stoneBrick.blockID);
		world.setBlock(i + 16, j + 5, k + 25, Block.stoneBrick.blockID);
		world.setBlock(i + 16, j + 5, k + 26, Block.stoneBrick.blockID);
		world.setBlock(i + 16, j + 5, k + 27, Block.stoneBrick.blockID);
		world.setBlock(i + 16, j + 5, k + 28, Block.stoneBrick.blockID);
		world.setBlock(i + 16, j + 5, k + 29, Block.stoneBrick.blockID);
		world.setBlock(i + 16, j + 5, k + 30, Block.stoneBrick.blockID);
		world.setBlock(i + 16, j + 5, k + 31, Block.stoneBrick.blockID);
		world.setBlock(i + 16, j + 5, k + 32, Block.stoneBrick.blockID);
		world.setBlock(i + 16, j + 5, k + 33, Block.stoneBrick.blockID);
		world.setBlock(i + 16, j + 5, k + 34, Block.stoneBrick.blockID);
		world.setBlock(i + 16, j + 5, k + 35, Block.stoneBrick.blockID);
		world.setBlock(i + 16, j + 5, k + 36, Block.stoneBrick.blockID);
		world.setBlock(i + 16, j + 5, k + 37, Block.stoneBrick.blockID);
		world.setBlock(i + 16, j + 5, k + 38, Block.stoneBrick.blockID);
		world.setBlock(i + 16, j + 5, k + 39, Block.stoneBrick.blockID);
		world.setBlock(i + 16, j + 5, k + 40, Block.stoneBrick.blockID);
		world.setBlock(i + 16, j + 5, k + 41, Block.stoneBrick.blockID);
		world.setBlock(i + 16, j + 5, k + 42, Block.stoneBrick.blockID);
		world.setBlock(i + 16, j + 5, k + 43, Block.stoneBrick.blockID);
		world.setBlock(i + 16, j + 5, k + 44, Block.stoneBrick.blockID);
		world.setBlock(i + 16, j + 5, k + 45, Block.stoneBrick.blockID);
		world.setBlock(i + 16, j + 5, k + 46, Block.stoneBrick.blockID);
		world.setBlock(i + 16, j + 5, k + 47, Block.stoneBrick.blockID);
		world.setBlock(i + 16, j + 5, k + 48, Block.stoneBrick.blockID);
		world.setBlock(i + 16, j + 5, k + 49, Block.stoneBrick.blockID);
		world.setBlock(i + 16, j + 5, k + 50, Block.glowStone.blockID);
		world.setBlock(i + 16, j + 5, k + 51, Block.stoneBrick.blockID);
		world.setBlock(i + 16, j + 6, k + 1, Block.stoneBrick.blockID);
		world.setBlock(i + 16, j + 6, k + 51, Block.stoneBrick.blockID);
		world.setBlock(i + 16, j + 7, k + 1, Block.stoneBrick.blockID);
		world.setBlock(i + 16, j + 7, k + 51, Block.stoneBrick.blockID);
		world.setBlock(i + 17, j + 0, k + 1, Block.stoneBrick.blockID);
		world.setBlockMetadataWithNotify(i + 17, j + 0, k + 6, Block.fire.blockID, 9);
		world.setBlockMetadataWithNotify(i + 17, j + 0, k + 7, Block.fire.blockID, 15);
		world.setBlockMetadataWithNotify(i + 17, j + 0, k + 8, Block.fire.blockID, 12);
		world.setBlockMetadataWithNotify(i + 17, j + 0, k + 9, Block.fire.blockID, 11);
		world.setBlockMetadataWithNotify(i + 17, j + 0, k + 10, Block.fire.blockID, 10);
		world.setBlockMetadataWithNotify(i + 17, j + 0, k + 11, Block.fire.blockID, 9);
		world.setBlockMetadataWithNotify(i + 17, j + 0, k + 12, Block.fire.blockID, 10);
		world.setBlockMetadataWithNotify(i + 17, j + 0, k + 13, Block.fire.blockID, 15);
		world.setBlockMetadataWithNotify(i + 17, j + 0, k + 14, Block.fire.blockID, 15);
		world.setBlockMetadataWithNotify(i + 17, j + 0, k + 15, Block.fire.blockID, 15);
		world.setBlockMetadataWithNotify(i + 17, j + 0, k + 16, Block.fire.blockID, 15);
		world.setBlockMetadataWithNotify(i + 17, j + 0, k + 17, Block.fire.blockID, 12);
		world.setBlockMetadataWithNotify(i + 17, j + 0, k + 18, Block.fire.blockID, 15);
		world.setBlock(i + 17, j + 0, k + 25, Block.stoneBrick.blockID);
		world.setBlock(i + 17, j + 0, k + 51, Block.stoneBrick.blockID);
		world.setBlock(i + 17, j + 1, k + 1, Block.stoneBrick.blockID);
		world.setBlock(i + 17, j + 1, k + 25, Block.stoneBrick.blockID);
		world.setBlock(i + 17, j + 1, k + 51, Block.stoneBrick.blockID);
		world.setBlock(i + 17, j + 2, k + 1, Block.stoneBrick.blockID);
		world.setBlock(i + 17, j + 2, k + 25, Block.stoneBrick.blockID);
		world.setBlock(i + 17, j + 2, k + 51, Block.stoneBrick.blockID);
		world.setBlock(i + 17, j + 3, k + 1, Block.stoneBrick.blockID);
		world.setBlock(i + 17, j + 3, k + 25, Block.stoneBrick.blockID);
		world.setBlock(i + 17, j + 3, k + 51, Block.stoneBrick.blockID);
		world.setBlock(i + 17, j + 4, k + 1, Block.stoneBrick.blockID);
		world.setBlock(i + 17, j + 4, k + 2, Block.glowStone.blockID);
		world.setBlock(i + 17, j + 4, k + 24, Block.glowStone.blockID);
		world.setBlock(i + 17, j + 4, k + 25, Block.stoneBrick.blockID);
		world.setBlock(i + 17, j + 4, k + 50, Block.glowStone.blockID);
		world.setBlock(i + 17, j + 4, k + 51, Block.stoneBrick.blockID);
		world.setBlock(i + 17, j + 5, k + 1, Block.stoneBrick.blockID);
		world.setBlock(i + 17, j + 5, k + 2, Block.glowStone.blockID);
		world.setBlock(i + 17, j + 5, k + 3, Block.stoneBrick.blockID);
		world.setBlock(i + 17, j + 5, k + 4, Block.stoneBrick.blockID);
